Workbook

Sheet Start
A1: Monthly close workbook
A3: How this workbook works
A4: 1. Numbers enter only through the grey Data_ tabs. The runner fills them from your sources; you can also paste query results by hand.
A5: 2. Every other tab is formulas reading the Data_ tabs for a 12-month window ending at the as-of month.
A6: 3. Judgment inputs (forecast and capacity) live on the Overrides tab, seeded from config.yaml. Type an override in a yellow cell to test a scenario.
A7: Bad entries are ignored, not fatal: a word, an error or an out-of-range number falls back to the model value. Set the switch on Overrides to OFF to undo every override at once.
A8: 4. Grey-shaded cells on Checks and Summary are for people and the agent: owners, explanations, commentary.
A10: This close
A11: As-of month | B11: =Data_Params!$B$2
A12: Generated | B12: =Data_Params!$B$13
A13: Usage grain | B13: =Data_Params!$B$9
A14: Sources connected | B14: =Data_Params!$B$12
A15: Usage data from | B15: =Data_Params!$B$10
A16: Usage data to | B16: =Data_Params!$B$11
A17: Checks flagged | B17: =COUNTIF(Checks!$G$5:$G$154,"FLAG")
A18: Overrides | B18: =Overrides!$C$5
A20: Color key: blue = input, black = formula, green = link to another tab, yellow = key assumption, grey tab = data.

Sheet Summary
A1: =Data_Params!$B$14&" | Monthly close"
A2: Formulas only. Start here, then Checks. Every figure traces to a Data_ sheet and from there to a query in /sql.
A3: As-of month | B3: =Data_Params!$B$2 | C3: Sources | D3: =Data_Params!$B$12 | F3: Overrides | G3: =Overrides!$C$5
A5: Metric | B5: =Monthly!H4 | C5: =Monthly!I4 | D5: =Monthly!J4 | E5: =Monthly!K4 | F5: =Monthly!L4 | G5: =Monthly!M4
A6: Billable tokens per day (B) | B6: =Monthly!H12 | C6: =Monthly!I12 | D6: =Monthly!J12 | E6: =Monthly!K12 | F6: =Monthly!L12 | G6: =Monthly!M12
A7: Growth in tokens per day | B7: =Monthly!H16 | C7: =Monthly!I16 | D7: =Monthly!J16 | E7: =Monthly!K16 | F7: =Monthly!L16 | G7: =Monthly!M16
A8: Net revenue ($k) | B8: =Monthly!H34 | C8: =Monthly!I34 | D8: =Monthly!J34 | E8: =Monthly!K34 | F8: =Monthly!L34 | G8: =Monthly!M34
A9: Annualized run-rate ($k) | B9: =Monthly!H36 | C9: =Monthly!I36 | D9: =Monthly!J36 | E9: =Monthly!K36 | F9: =Monthly!L36 | G9: =Monthly!M36
A10: Enterprise share of revenue | B10: =Monthly!H37 | C10: =Monthly!I37 | D10: =Monthly!J37 | E10: =Monthly!K37 | F10: =Monthly!L37 | G10: =Monthly!M37
A11: Realized net price per M tokens | B11: =Monthly!H38 | C11: =Monthly!I38 | D11: =Monthly!J38 | E11: =Monthly!K38 | F11: =Monthly!L38 | G11: =Monthly!M38
A12: Active accounts | B12: =Monthly!H44 | C12: =Monthly!I44 | D12: =Monthly!J44 | E12: =Monthly!K44 | F12: =Monthly!L44 | G12: =Monthly!M44
A13: Paying accounts | B13: =Monthly!H45 | C13: =Monthly!I45 | D13: =Monthly!J45 | E13: =Monthly!K45 | F13: =Monthly!L45 | G13: =Monthly!M45
A14: Failed calls (not billed) | B14: =Monthly!H46 | C14: =Monthly!I46 | D14: =Monthly!J46 | E14: =Monthly!K46 | F14: =Monthly!L46 | G14: =Monthly!M46
A16: Close checks
A17: Flagged for review | B17: =COUNTIF(Checks!$G$5:$G$154,"FLAG")
A18: Informational | B18: =COUNTIF(Checks!$G$5:$G$154,"INFO")
A19: Skipped (source not connected) | B19: =COUNTIF(Checks!$G$5:$G$154,"SKIP")
A20: Passed | B20: =COUNTIF(Checks!$G$5:$G$154,"PASS")
A21: $ impact of flagged items | B21: =SUMIF(Checks!$G$5:$G$154,"FLAG",Checks!$F$5:$F$154)
A23: Forecast, tokens per day (B)
A24: Scenario | B24: =EDATE(Data_Params!$B$2,1) | C24: =EDATE(Data_Params!$B$2,2) | D24: =EDATE(Data_Params!$B$2,3)
A25: Low | B25: =Forecast!B127 | C25: =Forecast!C127 | D25: =Forecast!D127
A26: Base | B26: =Forecast!E127 | C26: =Forecast!F127 | D26: =Forecast!G127
A27: High | B27: =Forecast!H127 | C27: =Forecast!I127 | D27: =Forecast!J127
A28: Net revenue, base ($k) | B28: =Forecast!E135 | C28: =Forecast!F135 | D28: =Forecast!G135
A29: Last month's forecast vs actual (total) | B29: =IF(Forecast!E143="","no forecast on file",Forecast!E143)
A30: GPUs to reserve for serving | B30: =Capacity!B27
A32: Commentary (written by finance, or drafted by the agent per AGENT_BRIEF.md and reviewed before it goes anywhere)

Sheet Checks
A1: =Data_Params!$B$14&" | Close checks"
A2: Rules in sql/50_checks.sql (Data_Checks). FLAG = a person must look. Columns I-L are for people and the agent; they are not overwritten by formulas.
A4: # | B4: Check | C4: Scope | D4: Expected | E4: Actual | F4: $ impact | G4: Status | H4: Detail | I4: Owner | J4: Next step | K4: Explanation (agent draft) | L4: Reviewed by
A5: =IF(INDEX(Data_Checks!$A:$A,1+1)="","",INDEX(Data_Checks!$A:$A,1+1)) | B5: =IF(INDEX(Data_Checks!$B:$B,1+1)="","",INDEX(Data_Checks!$B:$B,1+1)) | C5: =IF(INDEX(Data_Checks!$C:$C,1+1)="","",INDEX(Data_Checks!$C:$C,1+1)) | D5: =IF(INDEX(Data_Checks!$D:$D,1+1)="","",INDEX(Data_Checks!$D:$D,1+1)) | E5: =IF(INDEX(Data_Checks!$E:$E,1+1)="","",INDEX(Data_Checks!$E:$E,1+1)) | F5: =IF(INDEX(Data_Checks!$F:$F,1+1)="","",INDEX(Data_Checks!$F:$F,1+1)) | G5: =IF(INDEX(Data_Checks!$G:$G,1+1)="","",INDEX(Data_Checks!$G:$G,1+1)) | H5: =IF(INDEX(Data_Checks!$H:$H,1+1)="","",INDEX(Data_Checks!$H:$H,1+1))
A6: =IF(INDEX(Data_Checks!$A:$A,2+1)="","",INDEX(Data_Checks!$A:$A,2+1)) | B6: =IF(INDEX(Data_Checks!$B:$B,2+1)="","",INDEX(Data_Checks!$B:$B,2+1)) | C6: =IF(INDEX(Data_Checks!$C:$C,2+1)="","",INDEX(Data_Checks!$C:$C,2+1)) | D6: =IF(INDEX(Data_Checks!$D:$D,2+1)="","",INDEX(Data_Checks!$D:$D,2+1)) | E6: =IF(INDEX(Data_Checks!$E:$E,2+1)="","",INDEX(Data_Checks!$E:$E,2+1)) | F6: =IF(INDEX(Data_Checks!$F:$F,2+1)="","",INDEX(Data_Checks!$F:$F,2+1)) | G6: =IF(INDEX(Data_Checks!$G:$G,2+1)="","",INDEX(Data_Checks!$G:$G,2+1)) | H6: =IF(INDEX(Data_Checks!$H:$H,2+1)="","",INDEX(Data_Checks!$H:$H,2+1))
A7: =IF(INDEX(Data_Checks!$A:$A,3+1)="","",INDEX(Data_Checks!$A:$A,3+1)) | B7: =IF(INDEX(Data_Checks!$B:$B,3+1)="","",INDEX(Data_Checks!$B:$B,3+1)) | C7: =IF(INDEX(Data_Checks!$C:$C,3+1)="","",INDEX(Data_Checks!$C:$C,3+1)) | D7: =IF(INDEX(Data_Checks!$D:$D,3+1)="","",INDEX(Data_Checks!$D:$D,3+1)) | E7: =IF(INDEX(Data_Checks!$E:$E,3+1)="","",INDEX(Data_Checks!$E:$E,3+1)) | F7: =IF(INDEX(Data_Checks!$F:$F,3+1)="","",INDEX(Data_Checks!$F:$F,3+1)) | G7: =IF(INDEX(Data_Checks!$G:$G,3+1)="","",INDEX(Data_Checks!$G:$G,3+1)) | H7: =IF(INDEX(Data_Checks!$H:$H,3+1)="","",INDEX(Data_Checks!$H:$H,3+1))
A8: =IF(INDEX(Data_Checks!$A:$A,4+1)="","",INDEX(Data_Checks!$A:$A,4+1)) | B8: =IF(INDEX(Data_Checks!$B:$B,4+1)="","",INDEX(Data_Checks!$B:$B,4+1)) | C8: =IF(INDEX(Data_Checks!$C:$C,4+1)="","",INDEX(Data_Checks!$C:$C,4+1)) | D8: =IF(INDEX(Data_Checks!$D:$D,4+1)="","",INDEX(Data_Checks!$D:$D,4+1)) | E8: =IF(INDEX(Data_Checks!$E:$E,4+1)="","",INDEX(Data_Checks!$E:$E,4+1)) | F8: =IF(INDEX(Data_Checks!$F:$F,4+1)="","",INDEX(Data_Checks!$F:$F,4+1)) | G8: =IF(INDEX(Data_Checks!$G:$G,4+1)="","",INDEX(Data_Checks!$G:$G,4+1)) | H8: =IF(INDEX(Data_Checks!$H:$H,4+1)="","",INDEX(Data_Checks!$H:$H,4+1))
A9: =IF(INDEX(Data_Checks!$A:$A,5+1)="","",INDEX(Data_Checks!$A:$A,5+1)) | B9: =IF(INDEX(Data_Checks!$B:$B,5+1)="","",INDEX(Data_Checks!$B:$B,5+1)) | C9: =IF(INDEX(Data_Checks!$C:$C,5+1)="","",INDEX(Data_Checks!$C:$C,5+1)) | D9: =IF(INDEX(Data_Checks!$D:$D,5+1)="","",INDEX(Data_Checks!$D:$D,5+1)) | E9: =IF(INDEX(Data_Checks!$E:$E,5+1)="","",INDEX(Data_Checks!$E:$E,5+1)) | F9: =IF(INDEX(Data_Checks!$F:$F,5+1)="","",INDEX(Data_Checks!$F:$F,5+1)) | G9: =IF(INDEX(Data_Checks!$G:$G,5+1)="","",INDEX(Data_Checks!$G:$G,5+1)) | H9: =IF(INDEX(Data_Checks!$H:$H,5+1)="","",INDEX(Data_Checks!$H:$H,5+1))
A10: =IF(INDEX(Data_Checks!$A:$A,6+1)="","",INDEX(Data_Checks!$A:$A,6+1)) | B10: =IF(INDEX(Data_Checks!$B:$B,6+1)="","",INDEX(Data_Checks!$B:$B,6+1)) | C10: =IF(INDEX(Data_Checks!$C:$C,6+1)="","",INDEX(Data_Checks!$C:$C,6+1)) | D10: =IF(INDEX(Data_Checks!$D:$D,6+1)="","",INDEX(Data_Checks!$D:$D,6+1)) | E10: =IF(INDEX(Data_Checks!$E:$E,6+1)="","",INDEX(Data_Checks!$E:$E,6+1)) | F10: =IF(INDEX(Data_Checks!$F:$F,6+1)="","",INDEX(Data_Checks!$F:$F,6+1)) | G10: =IF(INDEX(Data_Checks!$G:$G,6+1)="","",INDEX(Data_Checks!$G:$G,6+1)) | H10: =IF(INDEX(Data_Checks!$H:$H,6+1)="","",INDEX(Data_Checks!$H:$H,6+1))
A11: =IF(INDEX(Data_Checks!$A:$A,7+1)="","",INDEX(Data_Checks!$A:$A,7+1)) | B11: =IF(INDEX(Data_Checks!$B:$B,7+1)="","",INDEX(Data_Checks!$B:$B,7+1)) | C11: =IF(INDEX(Data_Checks!$C:$C,7+1)="","",INDEX(Data_Checks!$C:$C,7+1)) | D11: =IF(INDEX(Data_Checks!$D:$D,7+1)="","",INDEX(Data_Checks!$D:$D,7+1)) | E11: =IF(INDEX(Data_Checks!$E:$E,7+1)="","",INDEX(Data_Checks!$E:$E,7+1)) | F11: =IF(INDEX(Data_Checks!$F:$F,7+1)="","",INDEX(Data_Checks!$F:$F,7+1)) | G11: =IF(INDEX(Data_Checks!$G:$G,7+1)="","",INDEX(Data_Checks!$G:$G,7+1)) | H11: =IF(INDEX(Data_Checks!$H:$H,7+1)="","",INDEX(Data_Checks!$H:$H,7+1))
A12: =IF(INDEX(Data_Checks!$A:$A,8+1)="","",INDEX(Data_Checks!$A:$A,8+1)) | B12: =IF(INDEX(Data_Checks!$B:$B,8+1)="","",INDEX(Data_Checks!$B:$B,8+1)) | C12: =IF(INDEX(Data_Checks!$C:$C,8+1)="","",INDEX(Data_Checks!$C:$C,8+1)) | D12: =IF(INDEX(Data_Checks!$D:$D,8+1)="","",INDEX(Data_Checks!$D:$D,8+1)) | E12: =IF(INDEX(Data_Checks!$E:$E,8+1)="","",INDEX(Data_Checks!$E:$E,8+1)) | F12: =IF(INDEX(Data_Checks!$F:$F,8+1)="","",INDEX(Data_Checks!$F:$F,8+1)) | G12: =IF(INDEX(Data_Checks!$G:$G,8+1)="","",INDEX(Data_Checks!$G:$G,8+1)) | H12: =IF(INDEX(Data_Checks!$H:$H,8+1)="","",INDEX(Data_Checks!$H:$H,8+1))
A13: =IF(INDEX(Data_Checks!$A:$A,9+1)="","",INDEX(Data_Checks!$A:$A,9+1)) | B13: =IF(INDEX(Data_Checks!$B:$B,9+1)="","",INDEX(Data_Checks!$B:$B,9+1)) | C13: =IF(INDEX(Data_Checks!$C:$C,9+1)="","",INDEX(Data_Checks!$C:$C,9+1)) | D13: =IF(INDEX(Data_Checks!$D:$D,9+1)="","",INDEX(Data_Checks!$D:$D,9+1)) | E13: =IF(INDEX(Data_Checks!$E:$E,9+1)="","",INDEX(Data_Checks!$E:$E,9+1)) | F13: =IF(INDEX(Data_Checks!$F:$F,9+1)="","",INDEX(Data_Checks!$F:$F,9+1)) | G13: =IF(INDEX(Data_Checks!$G:$G,9+1)="","",INDEX(Data_Checks!$G:$G,9+1)) | H13: =IF(INDEX(Data_Checks!$H:$H,9+1)="","",INDEX(Data_Checks!$H:$H,9+1))
A14: =IF(INDEX(Data_Checks!$A:$A,10+1)="","",INDEX(Data_Checks!$A:$A,10+1)) | B14: =IF(INDEX(Data_Checks!$B:$B,10+1)="","",INDEX(Data_Checks!$B:$B,10+1)) | C14: =IF(INDEX(Data_Checks!$C:$C,10+1)="","",INDEX(Data_Checks!$C:$C,10+1)) | D14: =IF(INDEX(Data_Checks!$D:$D,10+1)="","",INDEX(Data_Checks!$D:$D,10+1)) | E14: =IF(INDEX(Data_Checks!$E:$E,10+1)="","",INDEX(Data_Checks!$E:$E,10+1)) | F14: =IF(INDEX(Data_Checks!$F:$F,10+1)="","",INDEX(Data_Checks!$F:$F,10+1)) | G14: =IF(INDEX(Data_Checks!$G:$G,10+1)="","",INDEX(Data_Checks!$G:$G,10+1)) | H14: =IF(INDEX(Data_Checks!$H:$H,10+1)="","",INDEX(Data_Checks!$H:$H,10+1))
A15: =IF(INDEX(Data_Checks!$A:$A,11+1)="","",INDEX(Data_Checks!$A:$A,11+1)) | B15: =IF(INDEX(Data_Checks!$B:$B,11+1)="","",INDEX(Data_Checks!$B:$B,11+1)) | C15: =IF(INDEX(Data_Checks!$C:$C,11+1)="","",INDEX(Data_Checks!$C:$C,11+1)) | D15: =IF(INDEX(Data_Checks!$D:$D,11+1)="","",INDEX(Data_Checks!$D:$D,11+1)) | E15: =IF(INDEX(Data_Checks!$E:$E,11+1)="","",INDEX(Data_Checks!$E:$E,11+1)) | F15: =IF(INDEX(Data_Checks!$F:$F,11+1)="","",INDEX(Data_Checks!$F:$F,11+1)) | G15: =IF(INDEX(Data_Checks!$G:$G,11+1)="","",INDEX(Data_Checks!$G:$G,11+1)) | H15: =IF(INDEX(Data_Checks!$H:$H,11+1)="","",INDEX(Data_Checks!$H:$H,11+1))
A16: =IF(INDEX(Data_Checks!$A:$A,12+1)="","",INDEX(Data_Checks!$A:$A,12+1)) | B16: =IF(INDEX(Data_Checks!$B:$B,12+1)="","",INDEX(Data_Checks!$B:$B,12+1)) | C16: =IF(INDEX(Data_Checks!$C:$C,12+1)="","",INDEX(Data_Checks!$C:$C,12+1)) | D16: =IF(INDEX(Data_Checks!$D:$D,12+1)="","",INDEX(Data_Checks!$D:$D,12+1)) | E16: =IF(INDEX(Data_Checks!$E:$E,12+1)="","",INDEX(Data_Checks!$E:$E,12+1)) | F16: =IF(INDEX(Data_Checks!$F:$F,12+1)="","",INDEX(Data_Checks!$F:$F,12+1)) | G16: =IF(INDEX(Data_Checks!$G:$G,12+1)="","",INDEX(Data_Checks!$G:$G,12+1)) | H16: =IF(INDEX(Data_Checks!$H:$H,12+1)="","",INDEX(Data_Checks!$H:$H,12+1))
A17: =IF(INDEX(Data_Checks!$A:$A,13+1)="","",INDEX(Data_Checks!$A:$A,13+1)) | B17: =IF(INDEX(Data_Checks!$B:$B,13+1)="","",INDEX(Data_Checks!$B:$B,13+1)) | C17: =IF(INDEX(Data_Checks!$C:$C,13+1)="","",INDEX(Data_Checks!$C:$C,13+1)) | D17: =IF(INDEX(Data_Checks!$D:$D,13+1)="","",INDEX(Data_Checks!$D:$D,13+1)) | E17: =IF(INDEX(Data_Checks!$E:$E,13+1)="","",INDEX(Data_Checks!$E:$E,13+1)) | F17: =IF(INDEX(Data_Checks!$F:$F,13+1)="","",INDEX(Data_Checks!$F:$F,13+1)) | G17: =IF(INDEX(Data_Checks!$G:$G,13+1)="","",INDEX(Data_Checks!$G:$G,13+1)) | H17: =IF(INDEX(Data_Checks!$H:$H,13+1)="","",INDEX(Data_Checks!$H:$H,13+1))
A18: =IF(INDEX(Data_Checks!$A:$A,14+1)="","",INDEX(Data_Checks!$A:$A,14+1)) | B18: =IF(INDEX(Data_Checks!$B:$B,14+1)="","",INDEX(Data_Checks!$B:$B,14+1)) | C18: =IF(INDEX(Data_Checks!$C:$C,14+1)="","",INDEX(Data_Checks!$C:$C,14+1)) | D18: =IF(INDEX(Data_Checks!$D:$D,14+1)="","",INDEX(Data_Checks!$D:$D,14+1)) | E18: =IF(INDEX(Data_Checks!$E:$E,14+1)="","",INDEX(Data_Checks!$E:$E,14+1)) | F18: =IF(INDEX(Data_Checks!$F:$F,14+1)="","",INDEX(Data_Checks!$F:$F,14+1)) | G18: =IF(INDEX(Data_Checks!$G:$G,14+1)="","",INDEX(Data_Checks!$G:$G,14+1)) | H18: =IF(INDEX(Data_Checks!$H:$H,14+1)="","",INDEX(Data_Checks!$H:$H,14+1))
A19: =IF(INDEX(Data_Checks!$A:$A,15+1)="","",INDEX(Data_Checks!$A:$A,15+1)) | B19: =IF(INDEX(Data_Checks!$B:$B,15+1)="","",INDEX(Data_Checks!$B:$B,15+1)) | C19: =IF(INDEX(Data_Checks!$C:$C,15+1)="","",INDEX(Data_Checks!$C:$C,15+1)) | D19: =IF(INDEX(Data_Checks!$D:$D,15+1)="","",INDEX(Data_Checks!$D:$D,15+1)) | E19: =IF(INDEX(Data_Checks!$E:$E,15+1)="","",INDEX(Data_Checks!$E:$E,15+1)) | F19: =IF(INDEX(Data_Checks!$F:$F,15+1)="","",INDEX(Data_Checks!$F:$F,15+1)) | G19: =IF(INDEX(Data_Checks!$G:$G,15+1)="","",INDEX(Data_Checks!$G:$G,15+1)) | H19: =IF(INDEX(Data_Checks!$H:$H,15+1)="","",INDEX(Data_Checks!$H:$H,15+1))
A20: =IF(INDEX(Data_Checks!$A:$A,16+1)="","",INDEX(Data_Checks!$A:$A,16+1)) | B20: =IF(INDEX(Data_Checks!$B:$B,16+1)="","",INDEX(Data_Checks!$B:$B,16+1)) | C20: =IF(INDEX(Data_Checks!$C:$C,16+1)="","",INDEX(Data_Checks!$C:$C,16+1)) | D20: =IF(INDEX(Data_Checks!$D:$D,16+1)="","",INDEX(Data_Checks!$D:$D,16+1)) | E20: =IF(INDEX(Data_Checks!$E:$E,16+1)="","",INDEX(Data_Checks!$E:$E,16+1)) | F20: =IF(INDEX(Data_Checks!$F:$F,16+1)="","",INDEX(Data_Checks!$F:$F,16+1)) | G20: =IF(INDEX(Data_Checks!$G:$G,16+1)="","",INDEX(Data_Checks!$G:$G,16+1)) | H20: =IF(INDEX(Data_Checks!$H:$H,16+1)="","",INDEX(Data_Checks!$H:$H,16+1))
A21: =IF(INDEX(Data_Checks!$A:$A,17+1)="","",INDEX(Data_Checks!$A:$A,17+1)) | B21: =IF(INDEX(Data_Checks!$B:$B,17+1)="","",INDEX(Data_Checks!$B:$B,17+1)) | C21: =IF(INDEX(Data_Checks!$C:$C,17+1)="","",INDEX(Data_Checks!$C:$C,17+1)) | D21: =IF(INDEX(Data_Checks!$D:$D,17+1)="","",INDEX(Data_Checks!$D:$D,17+1)) | E21: =IF(INDEX(Data_Checks!$E:$E,17+1)="","",INDEX(Data_Checks!$E:$E,17+1)) | F21: =IF(INDEX(Data_Checks!$F:$F,17+1)="","",INDEX(Data_Checks!$F:$F,17+1)) | G21: =IF(INDEX(Data_Checks!$G:$G,17+1)="","",INDEX(Data_Checks!$G:$G,17+1)) | H21: =IF(INDEX(Data_Checks!$H:$H,17+1)="","",INDEX(Data_Checks!$H:$H,17+1))
A22: =IF(INDEX(Data_Checks!$A:$A,18+1)="","",INDEX(Data_Checks!$A:$A,18+1)) | B22: =IF(INDEX(Data_Checks!$B:$B,18+1)="","",INDEX(Data_Checks!$B:$B,18+1)) | C22: =IF(INDEX(Data_Checks!$C:$C,18+1)="","",INDEX(Data_Checks!$C:$C,18+1)) | D22: =IF(INDEX(Data_Checks!$D:$D,18+1)="","",INDEX(Data_Checks!$D:$D,18+1)) | E22: =IF(INDEX(Data_Checks!$E:$E,18+1)="","",INDEX(Data_Checks!$E:$E,18+1)) | F22: =IF(INDEX(Data_Checks!$F:$F,18+1)="","",INDEX(Data_Checks!$F:$F,18+1)) | G22: =IF(INDEX(Data_Checks!$G:$G,18+1)="","",INDEX(Data_Checks!$G:$G,18+1)) | H22: =IF(INDEX(Data_Checks!$H:$H,18+1)="","",INDEX(Data_Checks!$H:$H,18+1))
A23: =IF(INDEX(Data_Checks!$A:$A,19+1)="","",INDEX(Data_Checks!$A:$A,19+1)) | B23: =IF(INDEX(Data_Checks!$B:$B,19+1)="","",INDEX(Data_Checks!$B:$B,19+1)) | C23: =IF(INDEX(Data_Checks!$C:$C,19+1)="","",INDEX(Data_Checks!$C:$C,19+1)) | D23: =IF(INDEX(Data_Checks!$D:$D,19+1)="","",INDEX(Data_Checks!$D:$D,19+1)) | E23: =IF(INDEX(Data_Checks!$E:$E,19+1)="","",INDEX(Data_Checks!$E:$E,19+1)) | F23: =IF(INDEX(Data_Checks!$F:$F,19+1)="","",INDEX(Data_Checks!$F:$F,19+1)) | G23: =IF(INDEX(Data_Checks!$G:$G,19+1)="","",INDEX(Data_Checks!$G:$G,19+1)) | H23: =IF(INDEX(Data_Checks!$H:$H,19+1)="","",INDEX(Data_Checks!$H:$H,19+1))
A24: =IF(INDEX(Data_Checks!$A:$A,20+1)="","",INDEX(Data_Checks!$A:$A,20+1)) | B24: =IF(INDEX(Data_Checks!$B:$B,20+1)="","",INDEX(Data_Checks!$B:$B,20+1)) | C24: =IF(INDEX(Data_Checks!$C:$C,20+1)="","",INDEX(Data_Checks!$C:$C,20+1)) | D24: =IF(INDEX(Data_Checks!$D:$D,20+1)="","",INDEX(Data_Checks!$D:$D,20+1)) | E24: =IF(INDEX(Data_Checks!$E:$E,20+1)="","",INDEX(Data_Checks!$E:$E,20+1)) | F24: =IF(INDEX(Data_Checks!$F:$F,20+1)="","",INDEX(Data_Checks!$F:$F,20+1)) | G24: =IF(INDEX(Data_Checks!$G:$G,20+1)="","",INDEX(Data_Checks!$G:$G,20+1)) | H24: =IF(INDEX(Data_Checks!$H:$H,20+1)="","",INDEX(Data_Checks!$H:$H,20+1))
A25: =IF(INDEX(Data_Checks!$A:$A,21+1)="","",INDEX(Data_Checks!$A:$A,21+1)) | B25: =IF(INDEX(Data_Checks!$B:$B,21+1)="","",INDEX(Data_Checks!$B:$B,21+1)) | C25: =IF(INDEX(Data_Checks!$C:$C,21+1)="","",INDEX(Data_Checks!$C:$C,21+1)) | D25: =IF(INDEX(Data_Checks!$D:$D,21+1)="","",INDEX(Data_Checks!$D:$D,21+1)) | E25: =IF(INDEX(Data_Checks!$E:$E,21+1)="","",INDEX(Data_Checks!$E:$E,21+1)) | F25: =IF(INDEX(Data_Checks!$F:$F,21+1)="","",INDEX(Data_Checks!$F:$F,21+1)) | G25: =IF(INDEX(Data_Checks!$G:$G,21+1)="","",INDEX(Data_Checks!$G:$G,21+1)) | H25: =IF(INDEX(Data_Checks!$H:$H,21+1)="","",INDEX(Data_Checks!$H:$H,21+1))
A26: =IF(INDEX(Data_Checks!$A:$A,22+1)="","",INDEX(Data_Checks!$A:$A,22+1)) | B26: =IF(INDEX(Data_Checks!$B:$B,22+1)="","",INDEX(Data_Checks!$B:$B,22+1)) | C26: =IF(INDEX(Data_Checks!$C:$C,22+1)="","",INDEX(Data_Checks!$C:$C,22+1)) | D26: =IF(INDEX(Data_Checks!$D:$D,22+1)="","",INDEX(Data_Checks!$D:$D,22+1)) | E26: =IF(INDEX(Data_Checks!$E:$E,22+1)="","",INDEX(Data_Checks!$E:$E,22+1)) | F26: =IF(INDEX(Data_Checks!$F:$F,22+1)="","",INDEX(Data_Checks!$F:$F,22+1)) | G26: =IF(INDEX(Data_Checks!$G:$G,22+1)="","",INDEX(Data_Checks!$G:$G,22+1)) | H26: =IF(INDEX(Data_Checks!$H:$H,22+1)="","",INDEX(Data_Checks!$H:$H,22+1))
A27: =IF(INDEX(Data_Checks!$A:$A,23+1)="","",INDEX(Data_Checks!$A:$A,23+1)) | B27: =IF(INDEX(Data_Checks!$B:$B,23+1)="","",INDEX(Data_Checks!$B:$B,23+1)) | C27: =IF(INDEX(Data_Checks!$C:$C,23+1)="","",INDEX(Data_Checks!$C:$C,23+1)) | D27: =IF(INDEX(Data_Checks!$D:$D,23+1)="","",INDEX(Data_Checks!$D:$D,23+1)) | E27: =IF(INDEX(Data_Checks!$E:$E,23+1)="","",INDEX(Data_Checks!$E:$E,23+1)) | F27: =IF(INDEX(Data_Checks!$F:$F,23+1)="","",INDEX(Data_Checks!$F:$F,23+1)) | G27: =IF(INDEX(Data_Checks!$G:$G,23+1)="","",INDEX(Data_Checks!$G:$G,23+1)) | H27: =IF(INDEX(Data_Checks!$H:$H,23+1)="","",INDEX(Data_Checks!$H:$H,23+1))
A28: =IF(INDEX(Data_Checks!$A:$A,24+1)="","",INDEX(Data_Checks!$A:$A,24+1)) | B28: =IF(INDEX(Data_Checks!$B:$B,24+1)="","",INDEX(Data_Checks!$B:$B,24+1)) | C28: =IF(INDEX(Data_Checks!$C:$C,24+1)="","",INDEX(Data_Checks!$C:$C,24+1)) | D28: =IF(INDEX(Data_Checks!$D:$D,24+1)="","",INDEX(Data_Checks!$D:$D,24+1)) | E28: =IF(INDEX(Data_Checks!$E:$E,24+1)="","",INDEX(Data_Checks!$E:$E,24+1)) | F28: =IF(INDEX(Data_Checks!$F:$F,24+1)="","",INDEX(Data_Checks!$F:$F,24+1)) | G28: =IF(INDEX(Data_Checks!$G:$G,24+1)="","",INDEX(Data_Checks!$G:$G,24+1)) | H28: =IF(INDEX(Data_Checks!$H:$H,24+1)="","",INDEX(Data_Checks!$H:$H,24+1))
A29: =IF(INDEX(Data_Checks!$A:$A,25+1)="","",INDEX(Data_Checks!$A:$A,25+1)) | B29: =IF(INDEX(Data_Checks!$B:$B,25+1)="","",INDEX(Data_Checks!$B:$B,25+1)) | C29: =IF(INDEX(Data_Checks!$C:$C,25+1)="","",INDEX(Data_Checks!$C:$C,25+1)) | D29: =IF(INDEX(Data_Checks!$D:$D,25+1)="","",INDEX(Data_Checks!$D:$D,25+1)) | E29: =IF(INDEX(Data_Checks!$E:$E,25+1)="","",INDEX(Data_Checks!$E:$E,25+1)) | F29: =IF(INDEX(Data_Checks!$F:$F,25+1)="","",INDEX(Data_Checks!$F:$F,25+1)) | G29: =IF(INDEX(Data_Checks!$G:$G,25+1)="","",INDEX(Data_Checks!$G:$G,25+1)) | H29: =IF(INDEX(Data_Checks!$H:$H,25+1)="","",INDEX(Data_Checks!$H:$H,25+1))
A30: =IF(INDEX(Data_Checks!$A:$A,26+1)="","",INDEX(Data_Checks!$A:$A,26+1)) | B30: =IF(INDEX(Data_Checks!$B:$B,26+1)="","",INDEX(Data_Checks!$B:$B,26+1)) | C30: =IF(INDEX(Data_Checks!$C:$C,26+1)="","",INDEX(Data_Checks!$C:$C,26+1)) | D30: =IF(INDEX(Data_Checks!$D:$D,26+1)="","",INDEX(Data_Checks!$D:$D,26+1)) | E30: =IF(INDEX(Data_Checks!$E:$E,26+1)="","",INDEX(Data_Checks!$E:$E,26+1)) | F30: =IF(INDEX(Data_Checks!$F:$F,26+1)="","",INDEX(Data_Checks!$F:$F,26+1)) | G30: =IF(INDEX(Data_Checks!$G:$G,26+1)="","",INDEX(Data_Checks!$G:$G,26+1)) | H30: =IF(INDEX(Data_Checks!$H:$H,26+1)="","",INDEX(Data_Checks!$H:$H,26+1))
A31: =IF(INDEX(Data_Checks!$A:$A,27+1)="","",INDEX(Data_Checks!$A:$A,27+1)) | B31: =IF(INDEX(Data_Checks!$B:$B,27+1)="","",INDEX(Data_Checks!$B:$B,27+1)) | C31: =IF(INDEX(Data_Checks!$C:$C,27+1)="","",INDEX(Data_Checks!$C:$C,27+1)) | D31: =IF(INDEX(Data_Checks!$D:$D,27+1)="","",INDEX(Data_Checks!$D:$D,27+1)) | E31: =IF(INDEX(Data_Checks!$E:$E,27+1)="","",INDEX(Data_Checks!$E:$E,27+1)) | F31: =IF(INDEX(Data_Checks!$F:$F,27+1)="","",INDEX(Data_Checks!$F:$F,27+1)) | G31: =IF(INDEX(Data_Checks!$G:$G,27+1)="","",INDEX(Data_Checks!$G:$G,27+1)) | H31: =IF(INDEX(Data_Checks!$H:$H,27+1)="","",INDEX(Data_Checks!$H:$H,27+1))
A32: =IF(INDEX(Data_Checks!$A:$A,28+1)="","",INDEX(Data_Checks!$A:$A,28+1)) | B32: =IF(INDEX(Data_Checks!$B:$B,28+1)="","",INDEX(Data_Checks!$B:$B,28+1)) | C32: =IF(INDEX(Data_Checks!$C:$C,28+1)="","",INDEX(Data_Checks!$C:$C,28+1)) | D32: =IF(INDEX(Data_Checks!$D:$D,28+1)="","",INDEX(Data_Checks!$D:$D,28+1)) | E32: =IF(INDEX(Data_Checks!$E:$E,28+1)="","",INDEX(Data_Checks!$E:$E,28+1)) | F32: =IF(INDEX(Data_Checks!$F:$F,28+1)="","",INDEX(Data_Checks!$F:$F,28+1)) | G32: =IF(INDEX(Data_Checks!$G:$G,28+1)="","",INDEX(Data_Checks!$G:$G,28+1)) | H32: =IF(INDEX(Data_Checks!$H:$H,28+1)="","",INDEX(Data_Checks!$H:$H,28+1))
A33: =IF(INDEX(Data_Checks!$A:$A,29+1)="","",INDEX(Data_Checks!$A:$A,29+1)) | B33: =IF(INDEX(Data_Checks!$B:$B,29+1)="","",INDEX(Data_Checks!$B:$B,29+1)) | C33: =IF(INDEX(Data_Checks!$C:$C,29+1)="","",INDEX(Data_Checks!$C:$C,29+1)) | D33: =IF(INDEX(Data_Checks!$D:$D,29+1)="","",INDEX(Data_Checks!$D:$D,29+1)) | E33: =IF(INDEX(Data_Checks!$E:$E,29+1)="","",INDEX(Data_Checks!$E:$E,29+1)) | F33: =IF(INDEX(Data_Checks!$F:$F,29+1)="","",INDEX(Data_Checks!$F:$F,29+1)) | G33: =IF(INDEX(Data_Checks!$G:$G,29+1)="","",INDEX(Data_Checks!$G:$G,29+1)) | H33: =IF(INDEX(Data_Checks!$H:$H,29+1)="","",INDEX(Data_Checks!$H:$H,29+1))
A34: =IF(INDEX(Data_Checks!$A:$A,30+1)="","",INDEX(Data_Checks!$A:$A,30+1)) | B34: =IF(INDEX(Data_Checks!$B:$B,30+1)="","",INDEX(Data_Checks!$B:$B,30+1)) | C34: =IF(INDEX(Data_Checks!$C:$C,30+1)="","",INDEX(Data_Checks!$C:$C,30+1)) | D34: =IF(INDEX(Data_Checks!$D:$D,30+1)="","",INDEX(Data_Checks!$D:$D,30+1)) | E34: =IF(INDEX(Data_Checks!$E:$E,30+1)="","",INDEX(Data_Checks!$E:$E,30+1)) | F34: =IF(INDEX(Data_Checks!$F:$F,30+1)="","",INDEX(Data_Checks!$F:$F,30+1)) | G34: =IF(INDEX(Data_Checks!$G:$G,30+1)="","",INDEX(Data_Checks!$G:$G,30+1)) | H34: =IF(INDEX(Data_Checks!$H:$H,30+1)="","",INDEX(Data_Checks!$H:$H,30+1))
A35: =IF(INDEX(Data_Checks!$A:$A,31+1)="","",INDEX(Data_Checks!$A:$A,31+1)) | B35: =IF(INDEX(Data_Checks!$B:$B,31+1)="","",INDEX(Data_Checks!$B:$B,31+1)) | C35: =IF(INDEX(Data_Checks!$C:$C,31+1)="","",INDEX(Data_Checks!$C:$C,31+1)) | D35: =IF(INDEX(Data_Checks!$D:$D,31+1)="","",INDEX(Data_Checks!$D:$D,31+1)) | E35: =IF(INDEX(Data_Checks!$E:$E,31+1)="","",INDEX(Data_Checks!$E:$E,31+1)) | F35: =IF(INDEX(Data_Checks!$F:$F,31+1)="","",INDEX(Data_Checks!$F:$F,31+1)) | G35: =IF(INDEX(Data_Checks!$G:$G,31+1)="","",INDEX(Data_Checks!$G:$G,31+1)) | H35: =IF(INDEX(Data_Checks!$H:$H,31+1)="","",INDEX(Data_Checks!$H:$H,31+1))
A36: =IF(INDEX(Data_Checks!$A:$A,32+1)="","",INDEX(Data_Checks!$A:$A,32+1)) | B36: =IF(INDEX(Data_Checks!$B:$B,32+1)="","",INDEX(Data_Checks!$B:$B,32+1)) | C36: =IF(INDEX(Data_Checks!$C:$C,32+1)="","",INDEX(Data_Checks!$C:$C,32+1)) | D36: =IF(INDEX(Data_Checks!$D:$D,32+1)="","",INDEX(Data_Checks!$D:$D,32+1)) | E36: =IF(INDEX(Data_Checks!$E:$E,32+1)="","",INDEX(Data_Checks!$E:$E,32+1)) | F36: =IF(INDEX(Data_Checks!$F:$F,32+1)="","",INDEX(Data_Checks!$F:$F,32+1)) | G36: =IF(INDEX(Data_Checks!$G:$G,32+1)="","",INDEX(Data_Checks!$G:$G,32+1)) | H36: =IF(INDEX(Data_Checks!$H:$H,32+1)="","",INDEX(Data_Checks!$H:$H,32+1))
A37: =IF(INDEX(Data_Checks!$A:$A,33+1)="","",INDEX(Data_Checks!$A:$A,33+1)) | B37: =IF(INDEX(Data_Checks!$B:$B,33+1)="","",INDEX(Data_Checks!$B:$B,33+1)) | C37: =IF(INDEX(Data_Checks!$C:$C,33+1)="","",INDEX(Data_Checks!$C:$C,33+1)) | D37: =IF(INDEX(Data_Checks!$D:$D,33+1)="","",INDEX(Data_Checks!$D:$D,33+1)) | E37: =IF(INDEX(Data_Checks!$E:$E,33+1)="","",INDEX(Data_Checks!$E:$E,33+1)) | F37: =IF(INDEX(Data_Checks!$F:$F,33+1)="","",INDEX(Data_Checks!$F:$F,33+1)) | G37: =IF(INDEX(Data_Checks!$G:$G,33+1)="","",INDEX(Data_Checks!$G:$G,33+1)) | H37: =IF(INDEX(Data_Checks!$H:$H,33+1)="","",INDEX(Data_Checks!$H:$H,33+1))
A38: =IF(INDEX(Data_Checks!$A:$A,34+1)="","",INDEX(Data_Checks!$A:$A,34+1)) | B38: =IF(INDEX(Data_Checks!$B:$B,34+1)="","",INDEX(Data_Checks!$B:$B,34+1)) | C38: =IF(INDEX(Data_Checks!$C:$C,34+1)="","",INDEX(Data_Checks!$C:$C,34+1)) | D38: =IF(INDEX(Data_Checks!$D:$D,34+1)="","",INDEX(Data_Checks!$D:$D,34+1)) | E38: =IF(INDEX(Data_Checks!$E:$E,34+1)="","",INDEX(Data_Checks!$E:$E,34+1)) | F38: =IF(INDEX(Data_Checks!$F:$F,34+1)="","",INDEX(Data_Checks!$F:$F,34+1)) | G38: =IF(INDEX(Data_Checks!$G:$G,34+1)="","",INDEX(Data_Checks!$G:$G,34+1)) | H38: =IF(INDEX(Data_Checks!$H:$H,34+1)="","",INDEX(Data_Checks!$H:$H,34+1))
A39: =IF(INDEX(Data_Checks!$A:$A,35+1)="","",INDEX(Data_Checks!$A:$A,35+1)) | B39: =IF(INDEX(Data_Checks!$B:$B,35+1)="","",INDEX(Data_Checks!$B:$B,35+1)) | C39: =IF(INDEX(Data_Checks!$C:$C,35+1)="","",INDEX(Data_Checks!$C:$C,35+1)) | D39: =IF(INDEX(Data_Checks!$D:$D,35+1)="","",INDEX(Data_Checks!$D:$D,35+1)) | E39: =IF(INDEX(Data_Checks!$E:$E,35+1)="","",INDEX(Data_Checks!$E:$E,35+1)) | F39: =IF(INDEX(Data_Checks!$F:$F,35+1)="","",INDEX(Data_Checks!$F:$F,35+1)) | G39: =IF(INDEX(Data_Checks!$G:$G,35+1)="","",INDEX(Data_Checks!$G:$G,35+1)) | H39: =IF(INDEX(Data_Checks!$H:$H,35+1)="","",INDEX(Data_Checks!$H:$H,35+1))
A40: =IF(INDEX(Data_Checks!$A:$A,36+1)="","",INDEX(Data_Checks!$A:$A,36+1)) | B40: =IF(INDEX(Data_Checks!$B:$B,36+1)="","",INDEX(Data_Checks!$B:$B,36+1)) | C40: =IF(INDEX(Data_Checks!$C:$C,36+1)="","",INDEX(Data_Checks!$C:$C,36+1)) | D40: =IF(INDEX(Data_Checks!$D:$D,36+1)="","",INDEX(Data_Checks!$D:$D,36+1)) | E40: =IF(INDEX(Data_Checks!$E:$E,36+1)="","",INDEX(Data_Checks!$E:$E,36+1)) | F40: =IF(INDEX(Data_Checks!$F:$F,36+1)="","",INDEX(Data_Checks!$F:$F,36+1)) | G40: =IF(INDEX(Data_Checks!$G:$G,36+1)="","",INDEX(Data_Checks!$G:$G,36+1)) | H40: =IF(INDEX(Data_Checks!$H:$H,36+1)="","",INDEX(Data_Checks!$H:$H,36+1))
A41: =IF(INDEX(Data_Checks!$A:$A,37+1)="","",INDEX(Data_Checks!$A:$A,37+1)) | B41: =IF(INDEX(Data_Checks!$B:$B,37+1)="","",INDEX(Data_Checks!$B:$B,37+1)) | C41: =IF(INDEX(Data_Checks!$C:$C,37+1)="","",INDEX(Data_Checks!$C:$C,37+1)) | D41: =IF(INDEX(Data_Checks!$D:$D,37+1)="","",INDEX(Data_Checks!$D:$D,37+1)) | E41: =IF(INDEX(Data_Checks!$E:$E,37+1)="","",INDEX(Data_Checks!$E:$E,37+1)) | F41: =IF(INDEX(Data_Checks!$F:$F,37+1)="","",INDEX(Data_Checks!$F:$F,37+1)) | G41: =IF(INDEX(Data_Checks!$G:$G,37+1)="","",INDEX(Data_Checks!$G:$G,37+1)) | H41: =IF(INDEX(Data_Checks!$H:$H,37+1)="","",INDEX(Data_Checks!$H:$H,37+1))
...

Sheet Monthly
A1: =Data_Params!$B$14&" | Usage and revenue by month"
A2: Formulas only: every number reads the Data_ sheets. Tokens in billions, $ in thousands.
A4: Line | B4: =EDATE(Data_Params!$B$3,0) | C4: =EDATE(Data_Params!$B$3,1) | D4: =EDATE(Data_Params!$B$3,2) | E4: =EDATE(Data_Params!$B$3,3) | F4: =EDATE(Data_Params!$B$3,4) | G4: =EDATE(Data_Params!$B$3,5) | H4: =EDATE(Data_Params!$B$3,6) | I4: =EDATE(Data_Params!$B$3,7) | J4: =EDATE(Data_Params!$B$3,8) | K4: =EDATE(Data_Params!$B$3,9) | L4: =EDATE(Data_Params!$B$3,10) | M4: =EDATE(Data_Params!$B$3,11)
A5: Billable tokens (B)
A6: Enterprise | B6: =SUMIFS(Data_Monthly!$F:$F,Data_Monthly!$A:$A,B$4,Data_Monthly!$B:$B,"enterprise")/1E9 | C6: =SUMIFS(Data_Monthly!$F:$F,Data_Monthly!$A:$A,C$4,Data_Monthly!$B:$B,"enterprise")/1E9 | D6: =SUMIFS(Data_Monthly!$F:$F,Data_Monthly!$A:$A,D$4,Data_Monthly!$B:$B,"enterprise")/1E9 | E6: =SUMIFS(Data_Monthly!$F:$F,Data_Monthly!$A:$A,E$4,Data_Monthly!$B:$B,"enterprise")/1E9 | F6: =SUMIFS(Data_Monthly!$F:$F,Data_Monthly!$A:$A,F$4,Data_Monthly!$B:$B,"enterprise")/1E9 | G6: =SUMIFS(Data_Monthly!$F:$F,Data_Monthly!$A:$A,G$4,Data_Monthly!$B:$B,"enterprise")/1E9 | H6: =SUMIFS(Data_Monthly!$F:$F,Data_Monthly!$A:$A,H$4,Data_Monthly!$B:$B,"enterprise")/1E9 | I6: =SUMIFS(Data_Monthly!$F:$F,Data_Monthly!$A:$A,I$4,Data_Monthly!$B:$B,"enterprise")/1E9 | ... M6: =SUMIFS(Data_Monthly!$F:$F,Data_Monthly!$A:$A,M$4,Data_Monthly!$B:$B,"enterprise")/1E9
A7: Self-serve | B7: =SUMIFS(Data_Monthly!$F:$F,Data_Monthly!$A:$A,B$4,Data_Monthly!$B:$B,"self_serve")/1E9 | C7: =SUMIFS(Data_Monthly!$F:$F,Data_Monthly!$A:$A,C$4,Data_Monthly!$B:$B,"self_serve")/1E9 | D7: =SUMIFS(Data_Monthly!$F:$F,Data_Monthly!$A:$A,D$4,Data_Monthly!$B:$B,"self_serve")/1E9 | E7: =SUMIFS(Data_Monthly!$F:$F,Data_Monthly!$A:$A,E$4,Data_Monthly!$B:$B,"self_serve")/1E9 | F7: =SUMIFS(Data_Monthly!$F:$F,Data_Monthly!$A:$A,F$4,Data_Monthly!$B:$B,"self_serve")/1E9 | G7: =SUMIFS(Data_Monthly!$F:$F,Data_Monthly!$A:$A,G$4,Data_Monthly!$B:$B,"self_serve")/1E9 | H7: =SUMIFS(Data_Monthly!$F:$F,Data_Monthly!$A:$A,H$4,Data_Monthly!$B:$B,"self_serve")/1E9 | I7: =SUMIFS(Data_Monthly!$F:$F,Data_Monthly!$A:$A,I$4,Data_Monthly!$B:$B,"self_serve")/1E9 | ... M7: =SUMIFS(Data_Monthly!$F:$F,Data_Monthly!$A:$A,M$4,Data_Monthly!$B:$B,"self_serve")/1E9
A8: Gateways that don't pass customer IDs | B8: =SUMIFS(Data_Monthly!$F:$F,Data_Monthly!$A:$A,B$4,Data_Monthly!$B:$B,"gateway_aggregate")/1E9 | C8: =SUMIFS(Data_Monthly!$F:$F,Data_Monthly!$A:$A,C$4,Data_Monthly!$B:$B,"gateway_aggregate")/1E9 | D8: =SUMIFS(Data_Monthly!$F:$F,Data_Monthly!$A:$A,D$4,Data_Monthly!$B:$B,"gateway_aggregate")/1E9 | E8: =SUMIFS(Data_Monthly!$F:$F,Data_Monthly!$A:$A,E$4,Data_Monthly!$B:$B,"gateway_aggregate")/1E9 | F8: =SUMIFS(Data_Monthly!$F:$F,Data_Monthly!$A:$A,F$4,Data_Monthly!$B:$B,"gateway_aggregate")/1E9 | G8: =SUMIFS(Data_Monthly!$F:$F,Data_Monthly!$A:$A,G$4,Data_Monthly!$B:$B,"gateway_aggregate")/1E9 | H8: =SUMIFS(Data_Monthly!$F:$F,Data_Monthly!$A:$A,H$4,Data_Monthly!$B:$B,"gateway_aggregate")/1E9 | I8: =SUMIFS(Data_Monthly!$F:$F,Data_Monthly!$A:$A,I$4,Data_Monthly!$B:$B,"gateway_aggregate")/1E9 | ... M8: =SUMIFS(Data_Monthly!$F:$F,Data_Monthly!$A:$A,M$4,Data_Monthly!$B:$B,"gateway_aggregate")/1E9
A9: Unmatched accounts (fix the accounts source) | B9: =SUMIFS(Data_Monthly!$F:$F,Data_Monthly!$A:$A,B$4,Data_Monthly!$B:$B,"unmatched")/1E9 | C9: =SUMIFS(Data_Monthly!$F:$F,Data_Monthly!$A:$A,C$4,Data_Monthly!$B:$B,"unmatched")/1E9 | D9: =SUMIFS(Data_Monthly!$F:$F,Data_Monthly!$A:$A,D$4,Data_Monthly!$B:$B,"unmatched")/1E9 | E9: =SUMIFS(Data_Monthly!$F:$F,Data_Monthly!$A:$A,E$4,Data_Monthly!$B:$B,"unmatched")/1E9 | F9: =SUMIFS(Data_Monthly!$F:$F,Data_Monthly!$A:$A,F$4,Data_Monthly!$B:$B,"unmatched")/1E9 | G9: =SUMIFS(Data_Monthly!$F:$F,Data_Monthly!$A:$A,G$4,Data_Monthly!$B:$B,"unmatched")/1E9 | H9: =SUMIFS(Data_Monthly!$F:$F,Data_Monthly!$A:$A,H$4,Data_Monthly!$B:$B,"unmatched")/1E9 | I9: =SUMIFS(Data_Monthly!$F:$F,Data_Monthly!$A:$A,I$4,Data_Monthly!$B:$B,"unmatched")/1E9 | ... M9: =SUMIFS(Data_Monthly!$F:$F,Data_Monthly!$A:$A,M$4,Data_Monthly!$B:$B,"unmatched")/1E9
A10: Total billable tokens | B10: =SUM(B6:B9) | C10: =SUM(C6:C9) | D10: =SUM(D6:D9) | E10: =SUM(E6:E9) | F10: =SUM(F6:F9) | G10: =SUM(G6:G9) | H10: =SUM(H6:H9) | I10: =SUM(I6:I9) | ... M10: =SUM(M6:M9)
A11: Days of data in month | B11: =SUMIFS(Data_Months!$B:$B,Data_Months!$A:$A,B$4) | C11: =SUMIFS(Data_Months!$B:$B,Data_Months!$A:$A,C$4) | D11: =SUMIFS(Data_Months!$B:$B,Data_Months!$A:$A,D$4) | E11: =SUMIFS(Data_Months!$B:$B,Data_Months!$A:$A,E$4) | F11: =SUMIFS(Data_Months!$B:$B,Data_Months!$A:$A,F$4) | G11: =SUMIFS(Data_Months!$B:$B,Data_Months!$A:$A,G$4) | H11: =SUMIFS(Data_Months!$B:$B,Data_Months!$A:$A,H$4) | I11: =SUMIFS(Data_Months!$B:$B,Data_Months!$A:$A,I$4) | ... M11: =SUMIFS(Data_Months!$B:$B,Data_Months!$A:$A,M$4)
A12: Tokens per day (B) | B12: =IF(B11=0,0,B10/B11) | C12: =IF(C11=0,0,C10/C11) | D12: =IF(D11=0,0,D10/D11) | E12: =IF(E11=0,0,E10/E11) | F12: =IF(F11=0,0,F10/F11) | G12: =IF(G11=0,0,G10/G11) | H12: =IF(H11=0,0,H10/H11) | I12: =IF(I11=0,0,I10/I11) | ... M12: =IF(M11=0,0,M10/M11)
A13: Enterprise, per day | B13: =IF(B11=0,0,B6/B11) | C13: =IF(C11=0,0,C6/C11) | D13: =IF(D11=0,0,D6/D11) | E13: =IF(E11=0,0,E6/E11) | F13: =IF(F11=0,0,F6/F11) | G13: =IF(G11=0,0,G6/G11) | H13: =IF(H11=0,0,H6/H11) | I13: =IF(I11=0,0,I6/I11) | ... M13: =IF(M11=0,0,M6/M11)
A14: Self-serve, per day | B14: =IF(B11=0,0,B7/B11) | C14: =IF(C11=0,0,C7/C11) | D14: =IF(D11=0,0,D7/D11) | E14: =IF(E11=0,0,E7/E11) | F14: =IF(F11=0,0,F7/F11) | G14: =IF(G11=0,0,G7/G11) | H14: =IF(H11=0,0,H7/H11) | I14: =IF(I11=0,0,I7/I11) | ... M14: =IF(M11=0,0,M7/M11)
A15: Gateways that don't pass customer IDs, per day | B15: =IF(B11=0,0,B8/B11) | C15: =IF(C11=0,0,C8/C11) | D15: =IF(D11=0,0,D8/D11) | E15: =IF(E11=0,0,E8/E11) | F15: =IF(F11=0,0,F8/F11) | G15: =IF(G11=0,0,G8/G11) | H15: =IF(H11=0,0,H8/H11) | I15: =IF(I11=0,0,I8/I11) | ... M15: =IF(M11=0,0,M8/M11)
A16: Growth in tokens per day vs prior month | C16: =IF(B12=0,0,C12/B12-1) | D16: =IF(C12=0,0,D12/C12-1) | E16: =IF(D12=0,0,E12/D12-1) | F16: =IF(E12=0,0,F12/E12-1) | G16: =IF(F12=0,0,G12/F12-1) | H16: =IF(G12=0,0,H12/G12-1) | I16: =IF(H12=0,0,I12/H12-1) | J16: =IF(I12=0,0,J12/I12-1) | ... M16: =IF(L12=0,0,M12/L12-1)
A18: Billable tokens by channel (B)
A19: =IF(INDEX(Data_Lists!$B:$B,1+1)="","",INDEX(Data_Lists!$B:$B,1+1)) | B19: =IF($A19="","",SUMIFS(Data_Monthly!$F:$F,Data_Monthly!$A:$A,B$4,Data_Monthly!$C:$C,$A19)/1E9) | C19: =IF($A19="","",SUMIFS(Data_Monthly!$F:$F,Data_Monthly!$A:$A,C$4,Data_Monthly!$C:$C,$A19)/1E9) | D19: =IF($A19="","",SUMIFS(Data_Monthly!$F:$F,Data_Monthly!$A:$A,D$4,Data_Monthly!$C:$C,$A19)/1E9) | E19: =IF($A19="","",SUMIFS(Data_Monthly!$F:$F,Data_Monthly!$A:$A,E$4,Data_Monthly!$C:$C,$A19)/1E9) | F19: =IF($A19="","",SUMIFS(Data_Monthly!$F:$F,Data_Monthly!$A:$A,F$4,Data_Monthly!$C:$C,$A19)/1E9) | G19: =IF($A19="","",SUMIFS(Data_Monthly!$F:$F,Data_Monthly!$A:$A,G$4,Data_Monthly!$C:$C,$A19)/1E9) | H19: =IF($A19="","",SUMIFS(Data_Monthly!$F:$F,Data_Monthly!$A:$A,H$4,Data_Monthly!$C:$C,$A19)/1E9) | I19: =IF($A19="","",SUMIFS(Data_Monthly!$F:$F,Data_Monthly!$A:$A,I$4,Data_Monthly!$C:$C,$A19)/1E9) | ... M19: =IF($A19="","",SUMIFS(Data_Monthly!$F:$F,Data_Monthly!$A:$A,M$4,Data_Monthly!$C:$C,$A19)/1E9)
A20: =IF(INDEX(Data_Lists!$B:$B,2+1)="","",INDEX(Data_Lists!$B:$B,2+1)) | B20: =IF($A20="","",SUMIFS(Data_Monthly!$F:$F,Data_Monthly!$A:$A,B$4,Data_Monthly!$C:$C,$A20)/1E9) | C20: =IF($A20="","",SUMIFS(Data_Monthly!$F:$F,Data_Monthly!$A:$A,C$4,Data_Monthly!$C:$C,$A20)/1E9) | D20: =IF($A20="","",SUMIFS(Data_Monthly!$F:$F,Data_Monthly!$A:$A,D$4,Data_Monthly!$C:$C,$A20)/1E9) | E20: =IF($A20="","",SUMIFS(Data_Monthly!$F:$F,Data_Monthly!$A:$A,E$4,Data_Monthly!$C:$C,$A20)/1E9) | F20: =IF($A20="","",SUMIFS(Data_Monthly!$F:$F,Data_Monthly!$A:$A,F$4,Data_Monthly!$C:$C,$A20)/1E9) | G20: =IF($A20="","",SUMIFS(Data_Monthly!$F:$F,Data_Monthly!$A:$A,G$4,Data_Monthly!$C:$C,$A20)/1E9) | H20: =IF($A20="","",SUMIFS(Data_Monthly!$F:$F,Data_Monthly!$A:$A,H$4,Data_Monthly!$C:$C,$A20)/1E9) | I20: =IF($A20="","",SUMIFS(Data_Monthly!$F:$F,Data_Monthly!$A:$A,I$4,Data_Monthly!$C:$C,$A20)/1E9) | ... M20: =IF($A20="","",SUMIFS(Data_Monthly!$F:$F,Data_Monthly!$A:$A,M$4,Data_Monthly!$C:$C,$A20)/1E9)
A21: =IF(INDEX(Data_Lists!$B:$B,3+1)="","",INDEX(Data_Lists!$B:$B,3+1)) | B21: =IF($A21="","",SUMIFS(Data_Monthly!$F:$F,Data_Monthly!$A:$A,B$4,Data_Monthly!$C:$C,$A21)/1E9) | C21: =IF($A21="","",SUMIFS(Data_Monthly!$F:$F,Data_Monthly!$A:$A,C$4,Data_Monthly!$C:$C,$A21)/1E9) | D21: =IF($A21="","",SUMIFS(Data_Monthly!$F:$F,Data_Monthly!$A:$A,D$4,Data_Monthly!$C:$C,$A21)/1E9) | E21: =IF($A21="","",SUMIFS(Data_Monthly!$F:$F,Data_Monthly!$A:$A,E$4,Data_Monthly!$C:$C,$A21)/1E9) | F21: =IF($A21="","",SUMIFS(Data_Monthly!$F:$F,Data_Monthly!$A:$A,F$4,Data_Monthly!$C:$C,$A21)/1E9) | G21: =IF($A21="","",SUMIFS(Data_Monthly!$F:$F,Data_Monthly!$A:$A,G$4,Data_Monthly!$C:$C,$A21)/1E9) | H21: =IF($A21="","",SUMIFS(Data_Monthly!$F:$F,Data_Monthly!$A:$A,H$4,Data_Monthly!$C:$C,$A21)/1E9) | I21: =IF($A21="","",SUMIFS(Data_Monthly!$F:$F,Data_Monthly!$A:$A,I$4,Data_Monthly!$C:$C,$A21)/1E9) | ... M21: =IF($A21="","",SUMIFS(Data_Monthly!$F:$F,Data_Monthly!$A:$A,M$4,Data_Monthly!$C:$C,$A21)/1E9)
A22: =IF(INDEX(Data_Lists!$B:$B,4+1)="","",INDEX(Data_Lists!$B:$B,4+1)) | B22: =IF($A22="","",SUMIFS(Data_Monthly!$F:$F,Data_Monthly!$A:$A,B$4,Data_Monthly!$C:$C,$A22)/1E9) | C22: =IF($A22="","",SUMIFS(Data_Monthly!$F:$F,Data_Monthly!$A:$A,C$4,Data_Monthly!$C:$C,$A22)/1E9) | D22: =IF($A22="","",SUMIFS(Data_Monthly!$F:$F,Data_Monthly!$A:$A,D$4,Data_Monthly!$C:$C,$A22)/1E9) | E22: =IF($A22="","",SUMIFS(Data_Monthly!$F:$F,Data_Monthly!$A:$A,E$4,Data_Monthly!$C:$C,$A22)/1E9) | F22: =IF($A22="","",SUMIFS(Data_Monthly!$F:$F,Data_Monthly!$A:$A,F$4,Data_Monthly!$C:$C,$A22)/1E9) | G22: =IF($A22="","",SUMIFS(Data_Monthly!$F:$F,Data_Monthly!$A:$A,G$4,Data_Monthly!$C:$C,$A22)/1E9) | H22: =IF($A22="","",SUMIFS(Data_Monthly!$F:$F,Data_Monthly!$A:$A,H$4,Data_Monthly!$C:$C,$A22)/1E9) | I22: =IF($A22="","",SUMIFS(Data_Monthly!$F:$F,Data_Monthly!$A:$A,I$4,Data_Monthly!$C:$C,$A22)/1E9) | ... M22: =IF($A22="","",SUMIFS(Data_Monthly!$F:$F,Data_Monthly!$A:$A,M$4,Data_Monthly!$C:$C,$A22)/1E9)
A23: =IF(INDEX(Data_Lists!$B:$B,5+1)="","",INDEX(Data_Lists!$B:$B,5+1)) | B23: =IF($A23="","",SUMIFS(Data_Monthly!$F:$F,Data_Monthly!$A:$A,B$4,Data_Monthly!$C:$C,$A23)/1E9) | C23: =IF($A23="","",SUMIFS(Data_Monthly!$F:$F,Data_Monthly!$A:$A,C$4,Data_Monthly!$C:$C,$A23)/1E9) | D23: =IF($A23="","",SUMIFS(Data_Monthly!$F:$F,Data_Monthly!$A:$A,D$4,Data_Monthly!$C:$C,$A23)/1E9) | E23: =IF($A23="","",SUMIFS(Data_Monthly!$F:$F,Data_Monthly!$A:$A,E$4,Data_Monthly!$C:$C,$A23)/1E9) | F23: =IF($A23="","",SUMIFS(Data_Monthly!$F:$F,Data_Monthly!$A:$A,F$4,Data_Monthly!$C:$C,$A23)/1E9) | G23: =IF($A23="","",SUMIFS(Data_Monthly!$F:$F,Data_Monthly!$A:$A,G$4,Data_Monthly!$C:$C,$A23)/1E9) | H23: =IF($A23="","",SUMIFS(Data_Monthly!$F:$F,Data_Monthly!$A:$A,H$4,Data_Monthly!$C:$C,$A23)/1E9) | I23: =IF($A23="","",SUMIFS(Data_Monthly!$F:$F,Data_Monthly!$A:$A,I$4,Data_Monthly!$C:$C,$A23)/1E9) | ... M23: =IF($A23="","",SUMIFS(Data_Monthly!$F:$F,Data_Monthly!$A:$A,M$4,Data_Monthly!$C:$C,$A23)/1E9)
A24: =IF(INDEX(Data_Lists!$B:$B,6+1)="","",INDEX(Data_Lists!$B:$B,6+1)) | B24: =IF($A24="","",SUMIFS(Data_Monthly!$F:$F,Data_Monthly!$A:$A,B$4,Data_Monthly!$C:$C,$A24)/1E9) | C24: =IF($A24="","",SUMIFS(Data_Monthly!$F:$F,Data_Monthly!$A:$A,C$4,Data_Monthly!$C:$C,$A24)/1E9) | D24: =IF($A24="","",SUMIFS(Data_Monthly!$F:$F,Data_Monthly!$A:$A,D$4,Data_Monthly!$C:$C,$A24)/1E9) | E24: =IF($A24="","",SUMIFS(Data_Monthly!$F:$F,Data_Monthly!$A:$A,E$4,Data_Monthly!$C:$C,$A24)/1E9) | F24: =IF($A24="","",SUMIFS(Data_Monthly!$F:$F,Data_Monthly!$A:$A,F$4,Data_Monthly!$C:$C,$A24)/1E9) | G24: =IF($A24="","",SUMIFS(Data_Monthly!$F:$F,Data_Monthly!$A:$A,G$4,Data_Monthly!$C:$C,$A24)/1E9) | H24: =IF($A24="","",SUMIFS(Data_Monthly!$F:$F,Data_Monthly!$A:$A,H$4,Data_Monthly!$C:$C,$A24)/1E9) | I24: =IF($A24="","",SUMIFS(Data_Monthly!$F:$F,Data_Monthly!$A:$A,I$4,Data_Monthly!$C:$C,$A24)/1E9) | ... M24: =IF($A24="","",SUMIFS(Data_Monthly!$F:$F,Data_Monthly!$A:$A,M$4,Data_Monthly!$C:$C,$A24)/1E9)
A25: =IF(INDEX(Data_Lists!$B:$B,7+1)="","",INDEX(Data_Lists!$B:$B,7+1)) | B25: =IF($A25="","",SUMIFS(Data_Monthly!$F:$F,Data_Monthly!$A:$A,B$4,Data_Monthly!$C:$C,$A25)/1E9) | C25: =IF($A25="","",SUMIFS(Data_Monthly!$F:$F,Data_Monthly!$A:$A,C$4,Data_Monthly!$C:$C,$A25)/1E9) | D25: =IF($A25="","",SUMIFS(Data_Monthly!$F:$F,Data_Monthly!$A:$A,D$4,Data_Monthly!$C:$C,$A25)/1E9) | E25: =IF($A25="","",SUMIFS(Data_Monthly!$F:$F,Data_Monthly!$A:$A,E$4,Data_Monthly!$C:$C,$A25)/1E9) | F25: =IF($A25="","",SUMIFS(Data_Monthly!$F:$F,Data_Monthly!$A:$A,F$4,Data_Monthly!$C:$C,$A25)/1E9) | G25: =IF($A25="","",SUMIFS(Data_Monthly!$F:$F,Data_Monthly!$A:$A,G$4,Data_Monthly!$C:$C,$A25)/1E9) | H25: =IF($A25="","",SUMIFS(Data_Monthly!$F:$F,Data_Monthly!$A:$A,H$4,Data_Monthly!$C:$C,$A25)/1E9) | I25: =IF($A25="","",SUMIFS(Data_Monthly!$F:$F,Data_Monthly!$A:$A,I$4,Data_Monthly!$C:$C,$A25)/1E9) | ... M25: =IF($A25="","",SUMIFS(Data_Monthly!$F:$F,Data_Monthly!$A:$A,M$4,Data_Monthly!$C:$C,$A25)/1E9)
A26: =IF(INDEX(Data_Lists!$B:$B,8+1)="","",INDEX(Data_Lists!$B:$B,8+1)) | B26: =IF($A26="","",SUMIFS(Data_Monthly!$F:$F,Data_Monthly!$A:$A,B$4,Data_Monthly!$C:$C,$A26)/1E9) | C26: =IF($A26="","",SUMIFS(Data_Monthly!$F:$F,Data_Monthly!$A:$A,C$4,Data_Monthly!$C:$C,$A26)/1E9) | D26: =IF($A26="","",SUMIFS(Data_Monthly!$F:$F,Data_Monthly!$A:$A,D$4,Data_Monthly!$C:$C,$A26)/1E9) | E26: =IF($A26="","",SUMIFS(Data_Monthly!$F:$F,Data_Monthly!$A:$A,E$4,Data_Monthly!$C:$C,$A26)/1E9) | F26: =IF($A26="","",SUMIFS(Data_Monthly!$F:$F,Data_Monthly!$A:$A,F$4,Data_Monthly!$C:$C,$A26)/1E9) | G26: =IF($A26="","",SUMIFS(Data_Monthly!$F:$F,Data_Monthly!$A:$A,G$4,Data_Monthly!$C:$C,$A26)/1E9) | H26: =IF($A26="","",SUMIFS(Data_Monthly!$F:$F,Data_Monthly!$A:$A,H$4,Data_Monthly!$C:$C,$A26)/1E9) | I26: =IF($A26="","",SUMIFS(Data_Monthly!$F:$F,Data_Monthly!$A:$A,I$4,Data_Monthly!$C:$C,$A26)/1E9) | ... M26: =IF($A26="","",SUMIFS(Data_Monthly!$F:$F,Data_Monthly!$A:$A,M$4,Data_Monthly!$C:$C,$A26)/1E9)
A28: Net revenue ($k)
A29: Enterprise | B29: =SUMIFS(Data_Monthly!$L:$L,Data_Monthly!$A:$A,B$4,Data_Monthly!$B:$B,"enterprise")/1E3 | C29: =SUMIFS(Data_Monthly!$L:$L,Data_Monthly!$A:$A,C$4,Data_Monthly!$B:$B,"enterprise")/1E3 | D29: =SUMIFS(Data_Monthly!$L:$L,Data_Monthly!$A:$A,D$4,Data_Monthly!$B:$B,"enterprise")/1E3 | E29: =SUMIFS(Data_Monthly!$L:$L,Data_Monthly!$A:$A,E$4,Data_Monthly!$B:$B,"enterprise")/1E3 | F29: =SUMIFS(Data_Monthly!$L:$L,Data_Monthly!$A:$A,F$4,Data_Monthly!$B:$B,"enterprise")/1E3 | G29: =SUMIFS(Data_Monthly!$L:$L,Data_Monthly!$A:$A,G$4,Data_Monthly!$B:$B,"enterprise")/1E3 | H29: =SUMIFS(Data_Monthly!$L:$L,Data_Monthly!$A:$A,H$4,Data_Monthly!$B:$B,"enterprise")/1E3 | I29: =SUMIFS(Data_Monthly!$L:$L,Data_Monthly!$A:$A,I$4,Data_Monthly!$B:$B,"enterprise")/1E3 | ... M29: =SUMIFS(Data_Monthly!$L:$L,Data_Monthly!$A:$A,M$4,Data_Monthly!$B:$B,"enterprise")/1E3
A30: Self-serve | B30: =SUMIFS(Data_Monthly!$L:$L,Data_Monthly!$A:$A,B$4,Data_Monthly!$B:$B,"self_serve")/1E3 | C30: =SUMIFS(Data_Monthly!$L:$L,Data_Monthly!$A:$A,C$4,Data_Monthly!$B:$B,"self_serve")/1E3 | D30: =SUMIFS(Data_Monthly!$L:$L,Data_Monthly!$A:$A,D$4,Data_Monthly!$B:$B,"self_serve")/1E3 | E30: =SUMIFS(Data_Monthly!$L:$L,Data_Monthly!$A:$A,E$4,Data_Monthly!$B:$B,"self_serve")/1E3 | F30: =SUMIFS(Data_Monthly!$L:$L,Data_Monthly!$A:$A,F$4,Data_Monthly!$B:$B,"self_serve")/1E3 | G30: =SUMIFS(Data_Monthly!$L:$L,Data_Monthly!$A:$A,G$4,Data_Monthly!$B:$B,"self_serve")/1E3 | H30: =SUMIFS(Data_Monthly!$L:$L,Data_Monthly!$A:$A,H$4,Data_Monthly!$B:$B,"self_serve")/1E3 | I30: =SUMIFS(Data_Monthly!$L:$L,Data_Monthly!$A:$A,I$4,Data_Monthly!$B:$B,"self_serve")/1E3 | ... M30: =SUMIFS(Data_Monthly!$L:$L,Data_Monthly!$A:$A,M$4,Data_Monthly!$B:$B,"self_serve")/1E3
A31: Gateways that don't pass customer IDs | B31: =SUMIFS(Data_Monthly!$L:$L,Data_Monthly!$A:$A,B$4,Data_Monthly!$B:$B,"gateway_aggregate")/1E3 | C31: =SUMIFS(Data_Monthly!$L:$L,Data_Monthly!$A:$A,C$4,Data_Monthly!$B:$B,"gateway_aggregate")/1E3 | D31: =SUMIFS(Data_Monthly!$L:$L,Data_Monthly!$A:$A,D$4,Data_Monthly!$B:$B,"gateway_aggregate")/1E3 | E31: =SUMIFS(Data_Monthly!$L:$L,Data_Monthly!$A:$A,E$4,Data_Monthly!$B:$B,"gateway_aggregate")/1E3 | F31: =SUMIFS(Data_Monthly!$L:$L,Data_Monthly!$A:$A,F$4,Data_Monthly!$B:$B,"gateway_aggregate")/1E3 | G31: =SUMIFS(Data_Monthly!$L:$L,Data_Monthly!$A:$A,G$4,Data_Monthly!$B:$B,"gateway_aggregate")/1E3 | H31: =SUMIFS(Data_Monthly!$L:$L,Data_Monthly!$A:$A,H$4,Data_Monthly!$B:$B,"gateway_aggregate")/1E3 | I31: =SUMIFS(Data_Monthly!$L:$L,Data_Monthly!$A:$A,I$4,Data_Monthly!$B:$B,"gateway_aggregate")/1E3 | ... M31: =SUMIFS(Data_Monthly!$L:$L,Data_Monthly!$A:$A,M$4,Data_Monthly!$B:$B,"gateway_aggregate")/1E3
A32: Unmatched accounts (fix the accounts source) | B32: =SUMIFS(Data_Monthly!$L:$L,Data_Monthly!$A:$A,B$4,Data_Monthly!$B:$B,"unmatched")/1E3 | C32: =SUMIFS(Data_Monthly!$L:$L,Data_Monthly!$A:$A,C$4,Data_Monthly!$B:$B,"unmatched")/1E3 | D32: =SUMIFS(Data_Monthly!$L:$L,Data_Monthly!$A:$A,D$4,Data_Monthly!$B:$B,"unmatched")/1E3 | E32: =SUMIFS(Data_Monthly!$L:$L,Data_Monthly!$A:$A,E$4,Data_Monthly!$B:$B,"unmatched")/1E3 | F32: =SUMIFS(Data_Monthly!$L:$L,Data_Monthly!$A:$A,F$4,Data_Monthly!$B:$B,"unmatched")/1E3 | G32: =SUMIFS(Data_Monthly!$L:$L,Data_Monthly!$A:$A,G$4,Data_Monthly!$B:$B,"unmatched")/1E3 | H32: =SUMIFS(Data_Monthly!$L:$L,Data_Monthly!$A:$A,H$4,Data_Monthly!$B:$B,"unmatched")/1E3 | I32: =SUMIFS(Data_Monthly!$L:$L,Data_Monthly!$A:$A,I$4,Data_Monthly!$B:$B,"unmatched")/1E3 | ... M32: =SUMIFS(Data_Monthly!$L:$L,Data_Monthly!$A:$A,M$4,Data_Monthly!$B:$B,"unmatched")/1E3
A33: Manual adjustments (Overrides tab) | B33: =SUMIFS(Overrides!$G$46:$G$75,Overrides!$F$46:$F$75,B$4)/1E3 | C33: =SUMIFS(Overrides!$G$46:$G$75,Overrides!$F$46:$F$75,C$4)/1E3 | D33: =SUMIFS(Overrides!$G$46:$G$75,Overrides!$F$46:$F$75,D$4)/1E3 | E33: =SUMIFS(Overrides!$G$46:$G$75,Overrides!$F$46:$F$75,E$4)/1E3 | F33: =SUMIFS(Overrides!$G$46:$G$75,Overrides!$F$46:$F$75,F$4)/1E3 | G33: =SUMIFS(Overrides!$G$46:$G$75,Overrides!$F$46:$F$75,G$4)/1E3 | H33: =SUMIFS(Overrides!$G$46:$G$75,Overrides!$F$46:$F$75,H$4)/1E3 | I33: =SUMIFS(Overrides!$G$46:$G$75,Overrides!$F$46:$F$75,I$4)/1E3 | ... M33: =SUMIFS(Overrides!$G$46:$G$75,Overrides!$F$46:$F$75,M$4)/1E3
A34: Total net revenue | B34: =SUM(B29:B33) | C34: =SUM(C29:C33) | D34: =SUM(D29:D33) | E34: =SUM(E29:E33) | F34: =SUM(F29:F33) | G34: =SUM(G29:G33) | H34: =SUM(H29:H33) | I34: =SUM(I29:I33) | ... M34: =SUM(M29:M33)
A35: of which enterprise true-ups | B35: =SUMIFS(Data_Monthly!$K:$K,Data_Monthly!$A:$A,B$4)/1E3 | C35: =SUMIFS(Data_Monthly!$K:$K,Data_Monthly!$A:$A,C$4)/1E3 | D35: =SUMIFS(Data_Monthly!$K:$K,Data_Monthly!$A:$A,D$4)/1E3 | E35: =SUMIFS(Data_Monthly!$K:$K,Data_Monthly!$A:$A,E$4)/1E3 | F35: =SUMIFS(Data_Monthly!$K:$K,Data_Monthly!$A:$A,F$4)/1E3 | G35: =SUMIFS(Data_Monthly!$K:$K,Data_Monthly!$A:$A,G$4)/1E3 | H35: =SUMIFS(Data_Monthly!$K:$K,Data_Monthly!$A:$A,H$4)/1E3 | I35: =SUMIFS(Data_Monthly!$K:$K,Data_Monthly!$A:$A,I$4)/1E3 | ... M35: =SUMIFS(Data_Monthly!$K:$K,Data_Monthly!$A:$A,M$4)/1E3
A36: Annualized run-rate ($k) | B36: =IF(B11=0,0,B34/B11*365) | C36: =IF(C11=0,0,C34/C11*365) | D36: =IF(D11=0,0,D34/D11*365) | E36: =IF(E11=0,0,E34/E11*365) | F36: =IF(F11=0,0,F34/F11*365) | G36: =IF(G11=0,0,G34/G11*365) | H36: =IF(H11=0,0,H34/H11*365) | I36: =IF(I11=0,0,I34/I11*365) | ... M36: =IF(M11=0,0,M34/M11*365)
A37: Enterprise share of net revenue | B37: =IF(B34=0,0,B29/B34) | C37: =IF(C34=0,0,C29/C34) | D37: =IF(D34=0,0,D29/D34) | E37: =IF(E34=0,0,E29/E34) | F37: =IF(F34=0,0,F29/F34) | G37: =IF(G34=0,0,G29/G34) | H37: =IF(H34=0,0,H29/H34) | I37: =IF(I34=0,0,I29/I34) | ... M37: =IF(M34=0,0,M29/M34)
A38: Realized net price per M tokens ($) | B38: =IF(B10=0,0,B34/B10) | C38: =IF(C10=0,0,C34/C10) | D38: =IF(D10=0,0,D34/D10) | E38: =IF(E10=0,0,E34/E10) | F38: =IF(F10=0,0,F34/F10) | G38: =IF(G10=0,0,G34/G10) | H38: =IF(H10=0,0,H34/H10) | I38: =IF(I10=0,0,I34/I10) | ... M38: =IF(M10=0,0,M34/M10)
A40: Other lines
A41: List value of tokens ($k) | B41: =SUMIFS(Data_Monthly!$I:$I,Data_Monthly!$A:$A,B$4)/1000 | C41: =SUMIFS(Data_Monthly!$I:$I,Data_Monthly!$A:$A,C$4)/1000 | D41: =SUMIFS(Data_Monthly!$I:$I,Data_Monthly!$A:$A,D$4)/1000 | E41: =SUMIFS(Data_Monthly!$I:$I,Data_Monthly!$A:$A,E$4)/1000 | F41: =SUMIFS(Data_Monthly!$I:$I,Data_Monthly!$A:$A,F$4)/1000 | G41: =SUMIFS(Data_Monthly!$I:$I,Data_Monthly!$A:$A,G$4)/1000 | H41: =SUMIFS(Data_Monthly!$I:$I,Data_Monthly!$A:$A,H$4)/1000 | I41: =SUMIFS(Data_Monthly!$I:$I,Data_Monthly!$A:$A,I$4)/1000 | ... M41: =SUMIFS(Data_Monthly!$I:$I,Data_Monthly!$A:$A,M$4)/1000
A42: Free credit used ($k) | B42: =SUMIFS(Data_Monthly!$H:$H,Data_Monthly!$A:$A,B$4)/1000 | C42: =SUMIFS(Data_Monthly!$H:$H,Data_Monthly!$A:$A,C$4)/1000 | D42: =SUMIFS(Data_Monthly!$H:$H,Data_Monthly!$A:$A,D$4)/1000 | E42: =SUMIFS(Data_Monthly!$H:$H,Data_Monthly!$A:$A,E$4)/1000 | F42: =SUMIFS(Data_Monthly!$H:$H,Data_Monthly!$A:$A,F$4)/1000 | G42: =SUMIFS(Data_Monthly!$H:$H,Data_Monthly!$A:$A,G$4)/1000 | H42: =SUMIFS(Data_Monthly!$H:$H,Data_Monthly!$A:$A,H$4)/1000 | I42: =SUMIFS(Data_Monthly!$H:$H,Data_Monthly!$A:$A,I$4)/1000 | ... M42: =SUMIFS(Data_Monthly!$H:$H,Data_Monthly!$A:$A,M$4)/1000
A43: Gateway fees ($k) | B43: =SUMIFS(Data_Monthly!$M:$M,Data_Monthly!$A:$A,B$4)/1000 | C43: =SUMIFS(Data_Monthly!$M:$M,Data_Monthly!$A:$A,C$4)/1000 | D43: =SUMIFS(Data_Monthly!$M:$M,Data_Monthly!$A:$A,D$4)/1000 | E43: =SUMIFS(Data_Monthly!$M:$M,Data_Monthly!$A:$A,E$4)/1000 | F43: =SUMIFS(Data_Monthly!$M:$M,Data_Monthly!$A:$A,F$4)/1000 | G43: =SUMIFS(Data_Monthly!$M:$M,Data_Monthly!$A:$A,G$4)/1000 | H43: =SUMIFS(Data_Monthly!$M:$M,Data_Monthly!$A:$A,H$4)/1000 | I43: =SUMIFS(Data_Monthly!$M:$M,Data_Monthly!$A:$A,I$4)/1000 | ... M43: =SUMIFS(Data_Monthly!$M:$M,Data_Monthly!$A:$A,M$4)/1000
A44: Active accounts (gateways counted once) | B44: =SUMIFS(Data_Monthly!$D:$D,Data_Monthly!$A:$A,B$4) | C44: =SUMIFS(Data_Monthly!$D:$D,Data_Monthly!$A:$A,C$4) | D44: =SUMIFS(Data_Monthly!$D:$D,Data_Monthly!$A:$A,D$4) | E44: =SUMIFS(Data_Monthly!$D:$D,Data_Monthly!$A:$A,E$4) | F44: =SUMIFS(Data_Monthly!$D:$D,Data_Monthly!$A:$A,F$4) | G44: =SUMIFS(Data_Monthly!$D:$D,Data_Monthly!$A:$A,G$4) | H44: =SUMIFS(Data_Monthly!$D:$D,Data_Monthly!$A:$A,H$4) | I44: =SUMIFS(Data_Monthly!$D:$D,Data_Monthly!$A:$A,I$4) | ... M44: =SUMIFS(Data_Monthly!$D:$D,Data_Monthly!$A:$A,M$4)
...

Sheet UseCases
A1: =Data_Params!$B$14&" | Where usage comes from"
A2: Use case from the customer's project label when mapped (label_map), otherwise inferred from traffic shape (sql/20_use_case_rules.sql).
A4: Use case (B tokens) | B4: =EDATE(Data_Params!$B$3,0) | C4: =EDATE(Data_Params!$B$3,1) | D4: =EDATE(Data_Params!$B$3,2) | E4: =EDATE(Data_Params!$B$3,3) | F4: =EDATE(Data_Params!$B$3,4) | G4: =EDATE(Data_Params!$B$3,5) | H4: =EDATE(Data_Params!$B$3,6) | I4: =EDATE(Data_Params!$B$3,7) | J4: =EDATE(Data_Params!$B$3,8) | K4: =EDATE(Data_Params!$B$3,9) | L4: =EDATE(Data_Params!$B$3,10) | M4: =EDATE(Data_Params!$B$3,11) | N4: Share of latest month | O4: From label, latest month
A5: =IF(INDEX(Data_Lists!$C:$C,1+1)="","",INDEX(Data_Lists!$C:$C,1+1)) | B5: =IF($A5="","",SUMIFS(Data_UseCase!$C:$C,Data_UseCase!$A:$A,B$4,Data_UseCase!$B:$B,$A5)/1E9) | C5: =IF($A5="","",SUMIFS(Data_UseCase!$C:$C,Data_UseCase!$A:$A,C$4,Data_UseCase!$B:$B,$A5)/1E9) | D5: =IF($A5="","",SUMIFS(Data_UseCase!$C:$C,Data_UseCase!$A:$A,D$4,Data_UseCase!$B:$B,$A5)/1E9) | E5: =IF($A5="","",SUMIFS(Data_UseCase!$C:$C,Data_UseCase!$A:$A,E$4,Data_UseCase!$B:$B,$A5)/1E9) | F5: =IF($A5="","",SUMIFS(Data_UseCase!$C:$C,Data_UseCase!$A:$A,F$4,Data_UseCase!$B:$B,$A5)/1E9) | G5: =IF($A5="","",SUMIFS(Data_UseCase!$C:$C,Data_UseCase!$A:$A,G$4,Data_UseCase!$B:$B,$A5)/1E9) | H5: =IF($A5="","",SUMIFS(Data_UseCase!$C:$C,Data_UseCase!$A:$A,H$4,Data_UseCase!$B:$B,$A5)/1E9) | I5: =IF($A5="","",SUMIFS(Data_UseCase!$C:$C,Data_UseCase!$A:$A,I$4,Data_UseCase!$B:$B,$A5)/1E9) | ... M5: =IF($A5="","",SUMIFS(Data_UseCase!$C:$C,Data_UseCase!$A:$A,M$4,Data_UseCase!$B:$B,$A5)/1E9) | N5: =IF($A5="","",IF(M$20=0,0,M5/M$20)) | O5: =IF(OR($A5="",N(M5)=0),"",SUMIFS(Data_UseCase!$D:$D,Data_UseCase!$A:$A,M$4,Data_UseCase!$B:$B,$A5)/1E9/M5)
A6: =IF(INDEX(Data_Lists!$C:$C,2+1)="","",INDEX(Data_Lists!$C:$C,2+1)) | B6: =IF($A6="","",SUMIFS(Data_UseCase!$C:$C,Data_UseCase!$A:$A,B$4,Data_UseCase!$B:$B,$A6)/1E9) | C6: =IF($A6="","",SUMIFS(Data_UseCase!$C:$C,Data_UseCase!$A:$A,C$4,Data_UseCase!$B:$B,$A6)/1E9) | D6: =IF($A6="","",SUMIFS(Data_UseCase!$C:$C,Data_UseCase!$A:$A,D$4,Data_UseCase!$B:$B,$A6)/1E9) | E6: =IF($A6="","",SUMIFS(Data_UseCase!$C:$C,Data_UseCase!$A:$A,E$4,Data_UseCase!$B:$B,$A6)/1E9) | F6: =IF($A6="","",SUMIFS(Data_UseCase!$C:$C,Data_UseCase!$A:$A,F$4,Data_UseCase!$B:$B,$A6)/1E9) | G6: =IF($A6="","",SUMIFS(Data_UseCase!$C:$C,Data_UseCase!$A:$A,G$4,Data_UseCase!$B:$B,$A6)/1E9) | H6: =IF($A6="","",SUMIFS(Data_UseCase!$C:$C,Data_UseCase!$A:$A,H$4,Data_UseCase!$B:$B,$A6)/1E9) | I6: =IF($A6="","",SUMIFS(Data_UseCase!$C:$C,Data_UseCase!$A:$A,I$4,Data_UseCase!$B:$B,$A6)/1E9) | ... M6: =IF($A6="","",SUMIFS(Data_UseCase!$C:$C,Data_UseCase!$A:$A,M$4,Data_UseCase!$B:$B,$A6)/1E9) | N6: =IF($A6="","",IF(M$20=0,0,M6/M$20)) | O6: =IF(OR($A6="",N(M6)=0),"",SUMIFS(Data_UseCase!$D:$D,Data_UseCase!$A:$A,M$4,Data_UseCase!$B:$B,$A6)/1E9/M6)
A7: =IF(INDEX(Data_Lists!$C:$C,3+1)="","",INDEX(Data_Lists!$C:$C,3+1)) | B7: =IF($A7="","",SUMIFS(Data_UseCase!$C:$C,Data_UseCase!$A:$A,B$4,Data_UseCase!$B:$B,$A7)/1E9) | C7: =IF($A7="","",SUMIFS(Data_UseCase!$C:$C,Data_UseCase!$A:$A,C$4,Data_UseCase!$B:$B,$A7)/1E9) | D7: =IF($A7="","",SUMIFS(Data_UseCase!$C:$C,Data_UseCase!$A:$A,D$4,Data_UseCase!$B:$B,$A7)/1E9) | E7: =IF($A7="","",SUMIFS(Data_UseCase!$C:$C,Data_UseCase!$A:$A,E$4,Data_UseCase!$B:$B,$A7)/1E9) | F7: =IF($A7="","",SUMIFS(Data_UseCase!$C:$C,Data_UseCase!$A:$A,F$4,Data_UseCase!$B:$B,$A7)/1E9) | G7: =IF($A7="","",SUMIFS(Data_UseCase!$C:$C,Data_UseCase!$A:$A,G$4,Data_UseCase!$B:$B,$A7)/1E9) | H7: =IF($A7="","",SUMIFS(Data_UseCase!$C:$C,Data_UseCase!$A:$A,H$4,Data_UseCase!$B:$B,$A7)/1E9) | I7: =IF($A7="","",SUMIFS(Data_UseCase!$C:$C,Data_UseCase!$A:$A,I$4,Data_UseCase!$B:$B,$A7)/1E9) | ... M7: =IF($A7="","",SUMIFS(Data_UseCase!$C:$C,Data_UseCase!$A:$A,M$4,Data_UseCase!$B:$B,$A7)/1E9) | N7: =IF($A7="","",IF(M$20=0,0,M7/M$20)) | O7: =IF(OR($A7="",N(M7)=0),"",SUMIFS(Data_UseCase!$D:$D,Data_UseCase!$A:$A,M$4,Data_UseCase!$B:$B,$A7)/1E9/M7)
A8: =IF(INDEX(Data_Lists!$C:$C,4+1)="","",INDEX(Data_Lists!$C:$C,4+1)) | B8: =IF($A8="","",SUMIFS(Data_UseCase!$C:$C,Data_UseCase!$A:$A,B$4,Data_UseCase!$B:$B,$A8)/1E9) | C8: =IF($A8="","",SUMIFS(Data_UseCase!$C:$C,Data_UseCase!$A:$A,C$4,Data_UseCase!$B:$B,$A8)/1E9) | D8: =IF($A8="","",SUMIFS(Data_UseCase!$C:$C,Data_UseCase!$A:$A,D$4,Data_UseCase!$B:$B,$A8)/1E9) | E8: =IF($A8="","",SUMIFS(Data_UseCase!$C:$C,Data_UseCase!$A:$A,E$4,Data_UseCase!$B:$B,$A8)/1E9) | F8: =IF($A8="","",SUMIFS(Data_UseCase!$C:$C,Data_UseCase!$A:$A,F$4,Data_UseCase!$B:$B,$A8)/1E9) | G8: =IF($A8="","",SUMIFS(Data_UseCase!$C:$C,Data_UseCase!$A:$A,G$4,Data_UseCase!$B:$B,$A8)/1E9) | H8: =IF($A8="","",SUMIFS(Data_UseCase!$C:$C,Data_UseCase!$A:$A,H$4,Data_UseCase!$B:$B,$A8)/1E9) | I8: =IF($A8="","",SUMIFS(Data_UseCase!$C:$C,Data_UseCase!$A:$A,I$4,Data_UseCase!$B:$B,$A8)/1E9) | ... M8: =IF($A8="","",SUMIFS(Data_UseCase!$C:$C,Data_UseCase!$A:$A,M$4,Data_UseCase!$B:$B,$A8)/1E9) | N8: =IF($A8="","",IF(M$20=0,0,M8/M$20)) | O8: =IF(OR($A8="",N(M8)=0),"",SUMIFS(Data_UseCase!$D:$D,Data_UseCase!$A:$A,M$4,Data_UseCase!$B:$B,$A8)/1E9/M8)
A9: =IF(INDEX(Data_Lists!$C:$C,5+1)="","",INDEX(Data_Lists!$C:$C,5+1)) | B9: =IF($A9="","",SUMIFS(Data_UseCase!$C:$C,Data_UseCase!$A:$A,B$4,Data_UseCase!$B:$B,$A9)/1E9) | C9: =IF($A9="","",SUMIFS(Data_UseCase!$C:$C,Data_UseCase!$A:$A,C$4,Data_UseCase!$B:$B,$A9)/1E9) | D9: =IF($A9="","",SUMIFS(Data_UseCase!$C:$C,Data_UseCase!$A:$A,D$4,Data_UseCase!$B:$B,$A9)/1E9) | E9: =IF($A9="","",SUMIFS(Data_UseCase!$C:$C,Data_UseCase!$A:$A,E$4,Data_UseCase!$B:$B,$A9)/1E9) | F9: =IF($A9="","",SUMIFS(Data_UseCase!$C:$C,Data_UseCase!$A:$A,F$4,Data_UseCase!$B:$B,$A9)/1E9) | G9: =IF($A9="","",SUMIFS(Data_UseCase!$C:$C,Data_UseCase!$A:$A,G$4,Data_UseCase!$B:$B,$A9)/1E9) | H9: =IF($A9="","",SUMIFS(Data_UseCase!$C:$C,Data_UseCase!$A:$A,H$4,Data_UseCase!$B:$B,$A9)/1E9) | I9: =IF($A9="","",SUMIFS(Data_UseCase!$C:$C,Data_UseCase!$A:$A,I$4,Data_UseCase!$B:$B,$A9)/1E9) | ... M9: =IF($A9="","",SUMIFS(Data_UseCase!$C:$C,Data_UseCase!$A:$A,M$4,Data_UseCase!$B:$B,$A9)/1E9) | N9: =IF($A9="","",IF(M$20=0,0,M9/M$20)) | O9: =IF(OR($A9="",N(M9)=0),"",SUMIFS(Data_UseCase!$D:$D,Data_UseCase!$A:$A,M$4,Data_UseCase!$B:$B,$A9)/1E9/M9)
A10: =IF(INDEX(Data_Lists!$C:$C,6+1)="","",INDEX(Data_Lists!$C:$C,6+1)) | B10: =IF($A10="","",SUMIFS(Data_UseCase!$C:$C,Data_UseCase!$A:$A,B$4,Data_UseCase!$B:$B,$A10)/1E9) | C10: =IF($A10="","",SUMIFS(Data_UseCase!$C:$C,Data_UseCase!$A:$A,C$4,Data_UseCase!$B:$B,$A10)/1E9) | D10: =IF($A10="","",SUMIFS(Data_UseCase!$C:$C,Data_UseCase!$A:$A,D$4,Data_UseCase!$B:$B,$A10)/1E9) | E10: =IF($A10="","",SUMIFS(Data_UseCase!$C:$C,Data_UseCase!$A:$A,E$4,Data_UseCase!$B:$B,$A10)/1E9) | F10: =IF($A10="","",SUMIFS(Data_UseCase!$C:$C,Data_UseCase!$A:$A,F$4,Data_UseCase!$B:$B,$A10)/1E9) | G10: =IF($A10="","",SUMIFS(Data_UseCase!$C:$C,Data_UseCase!$A:$A,G$4,Data_UseCase!$B:$B,$A10)/1E9) | H10: =IF($A10="","",SUMIFS(Data_UseCase!$C:$C,Data_UseCase!$A:$A,H$4,Data_UseCase!$B:$B,$A10)/1E9) | I10: =IF($A10="","",SUMIFS(Data_UseCase!$C:$C,Data_UseCase!$A:$A,I$4,Data_UseCase!$B:$B,$A10)/1E9) | ... M10: =IF($A10="","",SUMIFS(Data_UseCase!$C:$C,Data_UseCase!$A:$A,M$4,Data_UseCase!$B:$B,$A10)/1E9) | N10: =IF($A10="","",IF(M$20=0,0,M10/M$20)) | O10: =IF(OR($A10="",N(M10)=0),"",SUMIFS(Data_UseCase!$D:$D,Data_UseCase!$A:$A,M$4,Data_UseCase!$B:$B,$A10)/1E9/M10)
A11: =IF(INDEX(Data_Lists!$C:$C,7+1)="","",INDEX(Data_Lists!$C:$C,7+1)) | B11: =IF($A11="","",SUMIFS(Data_UseCase!$C:$C,Data_UseCase!$A:$A,B$4,Data_UseCase!$B:$B,$A11)/1E9) | C11: =IF($A11="","",SUMIFS(Data_UseCase!$C:$C,Data_UseCase!$A:$A,C$4,Data_UseCase!$B:$B,$A11)/1E9) | D11: =IF($A11="","",SUMIFS(Data_UseCase!$C:$C,Data_UseCase!$A:$A,D$4,Data_UseCase!$B:$B,$A11)/1E9) | E11: =IF($A11="","",SUMIFS(Data_UseCase!$C:$C,Data_UseCase!$A:$A,E$4,Data_UseCase!$B:$B,$A11)/1E9) | F11: =IF($A11="","",SUMIFS(Data_UseCase!$C:$C,Data_UseCase!$A:$A,F$4,Data_UseCase!$B:$B,$A11)/1E9) | G11: =IF($A11="","",SUMIFS(Data_UseCase!$C:$C,Data_UseCase!$A:$A,G$4,Data_UseCase!$B:$B,$A11)/1E9) | H11: =IF($A11="","",SUMIFS(Data_UseCase!$C:$C,Data_UseCase!$A:$A,H$4,Data_UseCase!$B:$B,$A11)/1E9) | I11: =IF($A11="","",SUMIFS(Data_UseCase!$C:$C,Data_UseCase!$A:$A,I$4,Data_UseCase!$B:$B,$A11)/1E9) | ... M11: =IF($A11="","",SUMIFS(Data_UseCase!$C:$C,Data_UseCase!$A:$A,M$4,Data_UseCase!$B:$B,$A11)/1E9) | N11: =IF($A11="","",IF(M$20=0,0,M11/M$20)) | O11: =IF(OR($A11="",N(M11)=0),"",SUMIFS(Data_UseCase!$D:$D,Data_UseCase!$A:$A,M$4,Data_UseCase!$B:$B,$A11)/1E9/M11)
A12: =IF(INDEX(Data_Lists!$C:$C,8+1)="","",INDEX(Data_Lists!$C:$C,8+1)) | B12: =IF($A12="","",SUMIFS(Data_UseCase!$C:$C,Data_UseCase!$A:$A,B$4,Data_UseCase!$B:$B,$A12)/1E9) | C12: =IF($A12="","",SUMIFS(Data_UseCase!$C:$C,Data_UseCase!$A:$A,C$4,Data_UseCase!$B:$B,$A12)/1E9) | D12: =IF($A12="","",SUMIFS(Data_UseCase!$C:$C,Data_UseCase!$A:$A,D$4,Data_UseCase!$B:$B,$A12)/1E9) | E12: =IF($A12="","",SUMIFS(Data_UseCase!$C:$C,Data_UseCase!$A:$A,E$4,Data_UseCase!$B:$B,$A12)/1E9) | F12: =IF($A12="","",SUMIFS(Data_UseCase!$C:$C,Data_UseCase!$A:$A,F$4,Data_UseCase!$B:$B,$A12)/1E9) | G12: =IF($A12="","",SUMIFS(Data_UseCase!$C:$C,Data_UseCase!$A:$A,G$4,Data_UseCase!$B:$B,$A12)/1E9) | H12: =IF($A12="","",SUMIFS(Data_UseCase!$C:$C,Data_UseCase!$A:$A,H$4,Data_UseCase!$B:$B,$A12)/1E9) | I12: =IF($A12="","",SUMIFS(Data_UseCase!$C:$C,Data_UseCase!$A:$A,I$4,Data_UseCase!$B:$B,$A12)/1E9) | ... M12: =IF($A12="","",SUMIFS(Data_UseCase!$C:$C,Data_UseCase!$A:$A,M$4,Data_UseCase!$B:$B,$A12)/1E9) | N12: =IF($A12="","",IF(M$20=0,0,M12/M$20)) | O12: =IF(OR($A12="",N(M12)=0),"",SUMIFS(Data_UseCase!$D:$D,Data_UseCase!$A:$A,M$4,Data_UseCase!$B:$B,$A12)/1E9/M12)
