Workbook

Sheet Start
A1: Monthly close workbook
A3: How this workbook works
A4: 1. Numbers enter only through the grey Data_ tabs. The runner fills them from your sources; you can also paste query results by hand.
A5: 2. Every other tab is formulas reading the Data_ tabs for a 12-month window ending at the as-of month.
A6: 3. Judgment inputs (forecast and capacity) live on the Overrides tab, seeded from config.yaml. Type an override in a yellow cell to test a scenario.
A7: Bad entries are ignored, not fatal: a word, an error or an out-of-range number falls back to the model value. Set the switch on Overrides to OFF to undo every override at once.
A8: 4. Grey-shaded cells on Checks and Summary are for people and the agent: owners, explanations, commentary.
A10: This close
A11: As-of month | B11: =Data_Params!$B$2 -> 46419
A12: Generated | B12: =Data_Params!$B$13 -> 2026-10-08 12:54
A13: Usage grain | B13: =Data_Params!$B$9 -> daily
A14: Sources connected | B14: =Data_Params!$B$12 -> usage, accounts, contracts, pipeline, billing_ledger, gateway_statements, hourly, label_map
A15: Usage data from | B15: =Data_Params!$B$10 -> 46280
A16: Usage data to | B16: =Data_Params!$B$11 -> 46446
A17: Checks flagged | B17: =COUNTIF(Checks!$G$5:$G$154,"FLAG") -> 3
A18: Overrides | B18: =Overrides!$C$5 -> 0 input(s) and 0 adjustment(s) applied
A20: Color key: blue = input, black = formula, green = link to another tab, yellow = key assumption, grey tab = data.

Sheet Summary
A1: =Data_Params!$B$14&" | Monthly close" -> Example Co (synthetic data) | Monthly close
A2: Formulas only. Start here, then Checks. Every figure traces to a Data_ sheet and from there to a query in /sql.
A3: As-of month | B3: =Data_Params!$B$2 -> 46419 | C3: Sources | D3: =Data_Params!$B$12 -> usage, accounts, contracts, pipeline, billing_ledger, gateway_statements, hourly, label_map | F3: Overrides | G3: =Overrides!$C$5 -> 0 input(s) and 0 adjustment(s) applied
A5: Metric | B5: =Monthly!H4 -> 46266 | C5: =Monthly!I4 -> 46296 | D5: =Monthly!J4 -> 46327 | E5: =Monthly!K4 -> 46357 | F5: =Monthly!L4 -> 46388 | G5: =Monthly!M4 -> 46419
A6: Billable tokens per day (B) | B6: =Monthly!H12 -> 0.45434755 | C6: =Monthly!I12 -> 20.888752 | D6: =Monthly!J12 -> 72.944573 | E6: =Monthly!K12 -> 138.41306 | F6: =Monthly!L12 -> 182.18111 | G6: =Monthly!M12 -> 215.7228
A7: Growth in tokens per day | B7: =Monthly!H16 -> 0 | C7: =Monthly!I16 -> 44.97527 | D7: =Monthly!J16 -> 2.4920504 | E7: =Monthly!K16 -> 0.89751007 | F7: =Monthly!L16 -> 0.31621324 | G7: =Monthly!M16 -> 0.18411182
A8: Net revenue ($k) | B8: =Monthly!H34 -> 0.17380235 | C8: =Monthly!I34 -> 54.248666 | D8: =Monthly!J34 -> 114.92348 | E8: =Monthly!K34 -> 191.62524 | F8: =Monthly!L34 -> 233.34663 | G8: =Monthly!M34 -> 247.70515
A9: Annualized run-rate ($k) | B9: =Monthly!H36 -> 3.9648661 | C9: =Monthly!I36 -> 638.7343 | D9: =Monthly!J36 -> 1398.2357 | E9: =Monthly!K36 -> 2256.2327 | F9: =Monthly!L36 -> 2747.4684 | G9: =Monthly!M36 -> 3229.0135
A10: Enterprise share of revenue | B10: =Monthly!H37 -> 0 | C10: =Monthly!I37 -> 0.95735964 | D10: =Monthly!J37 -> 0.89552797 | E10: =Monthly!K37 -> 0.83387344 | F10: =Monthly!L37 -> 0.79468712 | G10: =Monthly!M37 -> 0.76750761
A11: Realized net price per M tokens | B11: =Monthly!H38 -> 0.023908232 | C11: =Monthly!I38 -> 0.083775087 | D11: =Monthly!J38 -> 0.052516349 | E11: =Monthly!K38 -> 0.04465951 | F11: =Monthly!L38 -> 0.041317734 | G11: =Monthly!M38 -> 0.041009167
A12: Active accounts | B12: =Monthly!H44 -> 205 | C12: =Monthly!I44 -> 386 | D12: =Monthly!J44 -> 448 | E12: =Monthly!K44 -> 496 | F12: =Monthly!L44 -> 576 | G12: =Monthly!M44 -> 680
A13: Paying accounts | B13: =Monthly!H45 -> 99 | C13: =Monthly!I45 -> 209 | D13: =Monthly!J45 -> 249 | E13: =Monthly!K45 -> 313 | F13: =Monthly!L45 -> 384 | G13: =Monthly!M45 -> 421
A14: Failed calls (not billed) | B14: =Monthly!H46 -> 0.0037498935 | C14: =Monthly!I46 -> 0.0058980202 | D14: =Monthly!J46 -> 0.0059310038 | E14: =Monthly!K46 -> 0.025171377 | F14: =Monthly!L46 -> 0.005939912 | G14: =Monthly!M46 -> 0.0059398741
A16: Close checks
A17: Flagged for review | B17: =COUNTIF(Checks!$G$5:$G$154,"FLAG") -> 3
A18: Informational | B18: =COUNTIF(Checks!$G$5:$G$154,"INFO") -> 8
A19: Skipped (source not connected) | B19: =COUNTIF(Checks!$G$5:$G$154,"SKIP") -> 1
A20: Passed | B20: =COUNTIF(Checks!$G$5:$G$154,"PASS") -> 51
A21: $ impact of flagged items | B21: =SUMIF(Checks!$G$5:$G$154,"FLAG",Checks!$F$5:$F$154) -> 3888.7147
A23: Forecast, tokens per day (B)
A24: Scenario | B24: =EDATE(Data_Params!$B$2,1) -> 46447 | C24: =EDATE(Data_Params!$B$2,2) -> 46478 | D24: =EDATE(Data_Params!$B$2,3) -> 46508
A25: Low | B25: =Forecast!B127 -> 226.97779 | C25: =Forecast!C127 -> 228.44125 | D25: =Forecast!D127 -> 228.44782
A26: Base | B26: =Forecast!E127 -> 248.56438 | C26: =Forecast!F127 -> 279.40283 | D26: =Forecast!G127 -> 317.13097
A27: High | B27: =Forecast!H127 -> 266.41364 | C27: =Forecast!I127 -> 323.31682 | D27: =Forecast!J127 -> 398.03836
A28: Net revenue, base ($k) | B28: =Forecast!E135 -> 294.7772 | C28: =Forecast!F135 -> 320.99496 | D28: =Forecast!G135 -> 374.31608
A29: Last month's forecast vs actual (total) | B29: =IF(Forecast!E143="","no forecast on file",Forecast!E143) -> -0.041539484
A30: GPUs to reserve for serving | B30: =Capacity!B27 -> 67
A32: Commentary (written by finance, or drafted by the agent per AGENT_BRIEF.md and reviewed before it goes anywhere)

Sheet Checks
A1: =Data_Params!$B$14&" | Close checks" -> Example Co (synthetic data) | Close checks
A2: Rules in sql/50_checks.sql (Data_Checks). FLAG = a person must look. Columns I-L are for people and the agent; they are not overwritten by formulas.
A4: # | B4: Check | C4: Scope | D4: Expected | E4: Actual | F4: $ impact | G4: Status | H4: Detail | I4: Owner | J4: Next step | K4: Explanation (agent draft) | L4: Reviewed by
A5: =IF(INDEX(Data_Checks!$A:$A,1+1)="","",INDEX(Data_Checks!$A:$A,1+1)) -> 4 | B5: =IF(INDEX(Data_Checks!$B:$B,1+1)="","",INDEX(Data_Checks!$B:$B,1+1)) -> Billed tokens tie to billable usage | C5: =IF(INDEX(Data_Checks!$C:$C,1+1)="","",INDEX(Data_Checks!$C:$C,1+1)) -> 2026-12 | D5: =IF(INDEX(Data_Checks!$D:$D,1+1)="","",INDEX(Data_Checks!$D:$D,1+1)) -> 3798184735378 | E5: =IF(INDEX(Data_Checks!$E:$E,1+1)="","",INDEX(Data_Checks!$E:$E,1+1)) -> 3875687837224 | F5: =IF(INDEX(Data_Checks!$F:$F,1+1)="","",INDEX(Data_Checks!$F:$F,1+1)) -> 2756.4944 | G5: =IF(INDEX(Data_Checks!$G:$G,1+1)="","",INDEX(Data_Checks!$G:$G,1+1)) -> FLAG | H5: =IF(INDEX(Data_Checks!$H:$H,1+1)="","",INDEX(Data_Checks!$H:$H,1+1)) -> 176 accounts billed for a different number of tokens than billable usage
A6: =IF(INDEX(Data_Checks!$A:$A,2+1)="","",INDEX(Data_Checks!$A:$A,2+1)) -> 6 | B6: =IF(INDEX(Data_Checks!$B:$B,2+1)="","",INDEX(Data_Checks!$B:$B,2+1)) -> Invoices use the right unit price | C6: =IF(INDEX(Data_Checks!$C:$C,2+1)="","",INDEX(Data_Checks!$C:$C,2+1)) -> 2027-01 | D6: =IF(INDEX(Data_Checks!$D:$D,2+1)="","",INDEX(Data_Checks!$D:$D,2+1)) -> 175335.73 | E6: =IF(INDEX(Data_Checks!$E:$E,2+1)="","",INDEX(Data_Checks!$E:$E,2+1)) -> 176794.48 | F6: =IF(INDEX(Data_Checks!$F:$F,2+1)="","",INDEX(Data_Checks!$F:$F,2+1)) -> 1458.7521 | G6: =IF(INDEX(Data_Checks!$G:$G,2+1)="","",INDEX(Data_Checks!$G:$G,2+1)) -> FLAG | H6: =IF(INDEX(Data_Checks!$H:$H,2+1)="","",INDEX(Data_Checks!$H:$H,2+1)) -> Meridian Legal at $0.042/M vs expected $0.0336/M
A7: =IF(INDEX(Data_Checks!$A:$A,3+1)="","",INDEX(Data_Checks!$A:$A,3+1)) -> 8 | B7: =IF(INDEX(Data_Checks!$B:$B,3+1)="","",INDEX(Data_Checks!$B:$B,3+1)) -> Gateway statement matches our logs | C7: =IF(INDEX(Data_Checks!$C:$C,3+1)="","",INDEX(Data_Checks!$C:$C,3+1)) -> openrouter 2027-01 | D7: =IF(INDEX(Data_Checks!$D:$D,3+1)="","",INDEX(Data_Checks!$D:$D,3+1)) -> 314743752869 | E7: =IF(INDEX(Data_Checks!$E:$E,3+1)="","",INDEX(Data_Checks!$E:$E,3+1)) -> 306560000000 | F7: =IF(INDEX(Data_Checks!$F:$F,3+1)="","",INDEX(Data_Checks!$F:$F,3+1)) -> -326.53174 | G7: =IF(INDEX(Data_Checks!$G:$G,3+1)="","",INDEX(Data_Checks!$G:$G,3+1)) -> FLAG | H7: =IF(INDEX(Data_Checks!$H:$H,3+1)="","",INDEX(Data_Checks!$H:$H,3+1)) -> Statement is -2.6% vs our logs
A8: =IF(INDEX(Data_Checks!$A:$A,4+1)="","",INDEX(Data_Checks!$A:$A,4+1)) -> 10 | B8: =IF(INDEX(Data_Checks!$B:$B,4+1)="","",INDEX(Data_Checks!$B:$B,4+1)) -> Enterprise usage below commitment | C8: =IF(INDEX(Data_Checks!$C:$C,4+1)="","",INDEX(Data_Checks!$C:$C,4+1)) -> Halcyon Games 2026-12 | D8: =IF(INDEX(Data_Checks!$D:$D,4+1)="","",INDEX(Data_Checks!$D:$D,4+1)) -> 15000 | E8: =IF(INDEX(Data_Checks!$E:$E,4+1)="","",INDEX(Data_Checks!$E:$E,4+1)) -> 9731.6831 | F8: =IF(INDEX(Data_Checks!$F:$F,4+1)="","",INDEX(Data_Checks!$F:$F,4+1)) -> 5268.3169 | G8: =IF(INDEX(Data_Checks!$G:$G,4+1)="","",INDEX(Data_Checks!$G:$G,4+1)) -> INFO | H8: =IF(INDEX(Data_Checks!$H:$H,4+1)="","",INDEX(Data_Checks!$H:$H,4+1)) -> Usage at 65.0% of commitment; true-up owed. Revenue is protected this month; renewal is the risk.
A9: =IF(INDEX(Data_Checks!$A:$A,5+1)="","",INDEX(Data_Checks!$A:$A,5+1)) -> 10 | B9: =IF(INDEX(Data_Checks!$B:$B,5+1)="","",INDEX(Data_Checks!$B:$B,5+1)) -> Enterprise usage below commitment | C9: =IF(INDEX(Data_Checks!$C:$C,5+1)="","",INDEX(Data_Checks!$C:$C,5+1)) -> Ledgerline Payments 2026-11 | D9: =IF(INDEX(Data_Checks!$D:$D,5+1)="","",INDEX(Data_Checks!$D:$D,5+1)) -> 40000 | E9: =IF(INDEX(Data_Checks!$E:$E,5+1)="","",INDEX(Data_Checks!$E:$E,5+1)) -> 26079.212 | F9: =IF(INDEX(Data_Checks!$F:$F,5+1)="","",INDEX(Data_Checks!$F:$F,5+1)) -> 13920.788 | G9: =IF(INDEX(Data_Checks!$G:$G,5+1)="","",INDEX(Data_Checks!$G:$G,5+1)) -> INFO | H9: =IF(INDEX(Data_Checks!$H:$H,5+1)="","",INDEX(Data_Checks!$H:$H,5+1)) -> Usage at 65.0% of commitment; true-up owed. Revenue is protected this month; renewal is the risk.
A10: =IF(INDEX(Data_Checks!$A:$A,6+1)="","",INDEX(Data_Checks!$A:$A,6+1)) -> 10 | B10: =IF(INDEX(Data_Checks!$B:$B,6+1)="","",INDEX(Data_Checks!$B:$B,6+1)) -> Enterprise usage below commitment | C10: =IF(INDEX(Data_Checks!$C:$C,6+1)="","",INDEX(Data_Checks!$C:$C,6+1)) -> Meridian Legal 2027-01 | D10: =IF(INDEX(Data_Checks!$D:$D,6+1)="","",INDEX(Data_Checks!$D:$D,6+1)) -> 12500 | E10: =IF(INDEX(Data_Checks!$E:$E,6+1)="","",INDEX(Data_Checks!$E:$E,6+1)) -> 5834.6763 | F10: =IF(INDEX(Data_Checks!$F:$F,6+1)="","",INDEX(Data_Checks!$F:$F,6+1)) -> 6665.3237 | G10: =IF(INDEX(Data_Checks!$G:$G,6+1)="","",INDEX(Data_Checks!$G:$G,6+1)) -> INFO | H10: =IF(INDEX(Data_Checks!$H:$H,6+1)="","",INDEX(Data_Checks!$H:$H,6+1)) -> Usage at 47.0% of commitment; true-up owed. Revenue is protected this month; renewal is the risk.
A11: =IF(INDEX(Data_Checks!$A:$A,7+1)="","",INDEX(Data_Checks!$A:$A,7+1)) -> 10 | B11: =IF(INDEX(Data_Checks!$B:$B,7+1)="","",INDEX(Data_Checks!$B:$B,7+1)) -> Enterprise usage below commitment | C11: =IF(INDEX(Data_Checks!$C:$C,7+1)="","",INDEX(Data_Checks!$C:$C,7+1)) -> Meridian Legal 2027-02 | D11: =IF(INDEX(Data_Checks!$D:$D,7+1)="","",INDEX(Data_Checks!$D:$D,7+1)) -> 12500 | E11: =IF(INDEX(Data_Checks!$E:$E,7+1)="","",INDEX(Data_Checks!$E:$E,7+1)) -> 8675.3028 | F11: =IF(INDEX(Data_Checks!$F:$F,7+1)="","",INDEX(Data_Checks!$F:$F,7+1)) -> 3824.6972 | G11: =IF(INDEX(Data_Checks!$G:$G,7+1)="","",INDEX(Data_Checks!$G:$G,7+1)) -> INFO | H11: =IF(INDEX(Data_Checks!$H:$H,7+1)="","",INDEX(Data_Checks!$H:$H,7+1)) -> Usage at 69.0% of commitment; true-up owed. Revenue is protected this month; renewal is the risk.
A12: =IF(INDEX(Data_Checks!$A:$A,8+1)="","",INDEX(Data_Checks!$A:$A,8+1)) -> 10 | B12: =IF(INDEX(Data_Checks!$B:$B,8+1)="","",INDEX(Data_Checks!$B:$B,8+1)) -> Enterprise usage below commitment | C12: =IF(INDEX(Data_Checks!$C:$C,8+1)="","",INDEX(Data_Checks!$C:$C,8+1)) -> Northwind Insurance 2026-12 | D12: =IF(INDEX(Data_Checks!$D:$D,8+1)="","",INDEX(Data_Checks!$D:$D,8+1)) -> 20000 | E12: =IF(INDEX(Data_Checks!$E:$E,8+1)="","",INDEX(Data_Checks!$E:$E,8+1)) -> 7777.388 | F12: =IF(INDEX(Data_Checks!$F:$F,8+1)="","",INDEX(Data_Checks!$F:$F,8+1)) -> 12222.612 | G12: =IF(INDEX(Data_Checks!$G:$G,8+1)="","",INDEX(Data_Checks!$G:$G,8+1)) -> INFO | H12: =IF(INDEX(Data_Checks!$H:$H,8+1)="","",INDEX(Data_Checks!$H:$H,8+1)) -> Usage at 39.0% of commitment; true-up owed. Revenue is protected this month; renewal is the risk.
A13: =IF(INDEX(Data_Checks!$A:$A,9+1)="","",INDEX(Data_Checks!$A:$A,9+1)) -> 10 | B13: =IF(INDEX(Data_Checks!$B:$B,9+1)="","",INDEX(Data_Checks!$B:$B,9+1)) -> Enterprise usage below commitment | C13: =IF(INDEX(Data_Checks!$C:$C,9+1)="","",INDEX(Data_Checks!$C:$C,9+1)) -> Northwind Insurance 2027-01 | D13: =IF(INDEX(Data_Checks!$D:$D,9+1)="","",INDEX(Data_Checks!$D:$D,9+1)) -> 20000 | E13: =IF(INDEX(Data_Checks!$E:$E,9+1)="","",INDEX(Data_Checks!$E:$E,9+1)) -> 9624.0229 | F13: =IF(INDEX(Data_Checks!$F:$F,9+1)="","",INDEX(Data_Checks!$F:$F,9+1)) -> 10375.977 | G13: =IF(INDEX(Data_Checks!$G:$G,9+1)="","",INDEX(Data_Checks!$G:$G,9+1)) -> INFO | H13: =IF(INDEX(Data_Checks!$H:$H,9+1)="","",INDEX(Data_Checks!$H:$H,9+1)) -> Usage at 48.0% of commitment; true-up owed. Revenue is protected this month; renewal is the risk.
A14: =IF(INDEX(Data_Checks!$A:$A,10+1)="","",INDEX(Data_Checks!$A:$A,10+1)) -> 10 | B14: =IF(INDEX(Data_Checks!$B:$B,10+1)="","",INDEX(Data_Checks!$B:$B,10+1)) -> Enterprise usage below commitment | C14: =IF(INDEX(Data_Checks!$C:$C,10+1)="","",INDEX(Data_Checks!$C:$C,10+1)) -> Northwind Insurance 2027-02 | D14: =IF(INDEX(Data_Checks!$D:$D,10+1)="","",INDEX(Data_Checks!$D:$D,10+1)) -> 20000 | E14: =IF(INDEX(Data_Checks!$E:$E,10+1)="","",INDEX(Data_Checks!$E:$E,10+1)) -> 9112.6607 | F14: =IF(INDEX(Data_Checks!$F:$F,10+1)="","",INDEX(Data_Checks!$F:$F,10+1)) -> 10887.339 | G14: =IF(INDEX(Data_Checks!$G:$G,10+1)="","",INDEX(Data_Checks!$G:$G,10+1)) -> INFO | H14: =IF(INDEX(Data_Checks!$H:$H,10+1)="","",INDEX(Data_Checks!$H:$H,10+1)) -> Usage at 46.0% of commitment; true-up owed. Revenue is protected this month; renewal is the risk.
A15: =IF(INDEX(Data_Checks!$A:$A,11+1)="","",INDEX(Data_Checks!$A:$A,11+1)) -> 10 | B15: =IF(INDEX(Data_Checks!$B:$B,11+1)="","",INDEX(Data_Checks!$B:$B,11+1)) -> Enterprise usage below commitment | C15: =IF(INDEX(Data_Checks!$C:$C,11+1)="","",INDEX(Data_Checks!$C:$C,11+1)) -> Sable Research 2027-02 | D15: =IF(INDEX(Data_Checks!$D:$D,11+1)="","",INDEX(Data_Checks!$D:$D,11+1)) -> 17500 | E15: =IF(INDEX(Data_Checks!$E:$E,11+1)="","",INDEX(Data_Checks!$E:$E,11+1)) -> 12418.124 | F15: =IF(INDEX(Data_Checks!$F:$F,11+1)="","",INDEX(Data_Checks!$F:$F,11+1)) -> 5081.8763 | G15: =IF(INDEX(Data_Checks!$G:$G,11+1)="","",INDEX(Data_Checks!$G:$G,11+1)) -> INFO | H15: =IF(INDEX(Data_Checks!$H:$H,11+1)="","",INDEX(Data_Checks!$H:$H,11+1)) -> Usage at 71.0% of commitment; true-up owed. Revenue is protected this month; renewal is the risk.
A16: =IF(INDEX(Data_Checks!$A:$A,12+1)="","",INDEX(Data_Checks!$A:$A,12+1)) -> 1 | B16: =IF(INDEX(Data_Checks!$B:$B,12+1)="","",INDEX(Data_Checks!$B:$B,12+1)) -> No duplicate request IDs in call logs | C16: =IF(INDEX(Data_Checks!$C:$C,12+1)="","",INDEX(Data_Checks!$C:$C,12+1)) -> all calls to close | D16: =IF(INDEX(Data_Checks!$D:$D,12+1)="","",INDEX(Data_Checks!$D:$D,12+1)) -> 0 | E16: =IF(INDEX(Data_Checks!$E:$E,12+1)="","",INDEX(Data_Checks!$E:$E,12+1)) | F16: =IF(INDEX(Data_Checks!$F:$F,12+1)="","",INDEX(Data_Checks!$F:$F,12+1)) -> 0 | G16: =IF(INDEX(Data_Checks!$G:$G,12+1)="","",INDEX(Data_Checks!$G:$G,12+1)) -> SKIP | H16: =IF(INDEX(Data_Checks!$H:$H,12+1)="","",INDEX(Data_Checks!$H:$H,12+1)) -> Needs call-level logs with request_id
A17: =IF(INDEX(Data_Checks!$A:$A,13+1)="","",INDEX(Data_Checks!$A:$A,13+1)) -> 2 | B17: =IF(INDEX(Data_Checks!$B:$B,13+1)="","",INDEX(Data_Checks!$B:$B,13+1)) -> No missing days in usage data | C17: =IF(INDEX(Data_Checks!$C:$C,13+1)="","",INDEX(Data_Checks!$C:$C,13+1)) -> 2026-09-15 to 2027-02-28 | D17: =IF(INDEX(Data_Checks!$D:$D,13+1)="","",INDEX(Data_Checks!$D:$D,13+1)) -> 167 | E17: =IF(INDEX(Data_Checks!$E:$E,13+1)="","",INDEX(Data_Checks!$E:$E,13+1)) -> 167 | F17: =IF(INDEX(Data_Checks!$F:$F,13+1)="","",INDEX(Data_Checks!$F:$F,13+1)) -> 0 | G17: =IF(INDEX(Data_Checks!$G:$G,13+1)="","",INDEX(Data_Checks!$G:$G,13+1)) -> PASS | H17: =IF(INDEX(Data_Checks!$H:$H,13+1)="","",INDEX(Data_Checks!$H:$H,13+1)) -> Days with usage vs days in period. A gap usually means a failed export, not a quiet day.
A18: =IF(INDEX(Data_Checks!$A:$A,14+1)="","",INDEX(Data_Checks!$A:$A,14+1)) -> 3 | B18: =IF(INDEX(Data_Checks!$B:$B,14+1)="","",INDEX(Data_Checks!$B:$B,14+1)) -> All usage belongs to a known account | C18: =IF(INDEX(Data_Checks!$C:$C,14+1)="","",INDEX(Data_Checks!$C:$C,14+1)) -> reporting window | D18: =IF(INDEX(Data_Checks!$D:$D,14+1)="","",INDEX(Data_Checks!$D:$D,14+1)) -> 0 | E18: =IF(INDEX(Data_Checks!$E:$E,14+1)="","",INDEX(Data_Checks!$E:$E,14+1)) -> 0 | F18: =IF(INDEX(Data_Checks!$F:$F,14+1)="","",INDEX(Data_Checks!$F:$F,14+1)) -> 0 | G18: =IF(INDEX(Data_Checks!$G:$G,14+1)="","",INDEX(Data_Checks!$G:$G,14+1)) -> PASS | H18: =IF(INDEX(Data_Checks!$H:$H,14+1)="","",INDEX(Data_Checks!$H:$H,14+1)) -> 0 account IDs in usage are missing from the accounts source
A19: =IF(INDEX(Data_Checks!$A:$A,15+1)="","",INDEX(Data_Checks!$A:$A,15+1)) -> 4 | B19: =IF(INDEX(Data_Checks!$B:$B,15+1)="","",INDEX(Data_Checks!$B:$B,15+1)) -> Billed tokens tie to billable usage | C19: =IF(INDEX(Data_Checks!$C:$C,15+1)="","",INDEX(Data_Checks!$C:$C,15+1)) -> 2026-09 | D19: =IF(INDEX(Data_Checks!$D:$D,15+1)="","",INDEX(Data_Checks!$D:$D,15+1)) -> 3100670156 | E19: =IF(INDEX(Data_Checks!$E:$E,15+1)="","",INDEX(Data_Checks!$E:$E,15+1)) -> 3100670156 | F19: =IF(INDEX(Data_Checks!$F:$F,15+1)="","",INDEX(Data_Checks!$F:$F,15+1)) -> 0 | G19: =IF(INDEX(Data_Checks!$G:$G,15+1)="","",INDEX(Data_Checks!$G:$G,15+1)) -> PASS | H19: =IF(INDEX(Data_Checks!$H:$H,15+1)="","",INDEX(Data_Checks!$H:$H,15+1)) -> 0 accounts billed for a different number of tokens than billable usage
A20: =IF(INDEX(Data_Checks!$A:$A,16+1)="","",INDEX(Data_Checks!$A:$A,16+1)) -> 4 | B20: =IF(INDEX(Data_Checks!$B:$B,16+1)="","",INDEX(Data_Checks!$B:$B,16+1)) -> Billed tokens tie to billable usage | C20: =IF(INDEX(Data_Checks!$C:$C,16+1)="","",INDEX(Data_Checks!$C:$C,16+1)) -> 2026-10 | D20: =IF(INDEX(Data_Checks!$D:$D,16+1)="","",INDEX(Data_Checks!$D:$D,16+1)) -> 620098291596 | E20: =IF(INDEX(Data_Checks!$E:$E,16+1)="","",INDEX(Data_Checks!$E:$E,16+1)) -> 620098291596 | F20: =IF(INDEX(Data_Checks!$F:$F,16+1)="","",INDEX(Data_Checks!$F:$F,16+1)) -> 0 | G20: =IF(INDEX(Data_Checks!$G:$G,16+1)="","",INDEX(Data_Checks!$G:$G,16+1)) -> PASS | H20: =IF(INDEX(Data_Checks!$H:$H,16+1)="","",INDEX(Data_Checks!$H:$H,16+1)) -> 0 accounts billed for a different number of tokens than billable usage
A21: =IF(INDEX(Data_Checks!$A:$A,17+1)="","",INDEX(Data_Checks!$A:$A,17+1)) -> 4 | B21: =IF(INDEX(Data_Checks!$B:$B,17+1)="","",INDEX(Data_Checks!$B:$B,17+1)) -> Billed tokens tie to billable usage | C21: =IF(INDEX(Data_Checks!$C:$C,17+1)="","",INDEX(Data_Checks!$C:$C,17+1)) -> 2026-11 | D21: =IF(INDEX(Data_Checks!$D:$D,17+1)="","",INDEX(Data_Checks!$D:$D,17+1)) -> 2026111033189 | E21: =IF(INDEX(Data_Checks!$E:$E,17+1)="","",INDEX(Data_Checks!$E:$E,17+1)) -> 2026111033189 | F21: =IF(INDEX(Data_Checks!$F:$F,17+1)="","",INDEX(Data_Checks!$F:$F,17+1)) -> 0 | G21: =IF(INDEX(Data_Checks!$G:$G,17+1)="","",INDEX(Data_Checks!$G:$G,17+1)) -> PASS | H21: =IF(INDEX(Data_Checks!$H:$H,17+1)="","",INDEX(Data_Checks!$H:$H,17+1)) -> 0 accounts billed for a different number of tokens than billable usage
A22: =IF(INDEX(Data_Checks!$A:$A,18+1)="","",INDEX(Data_Checks!$A:$A,18+1)) -> 4 | B22: =IF(INDEX(Data_Checks!$B:$B,18+1)="","",INDEX(Data_Checks!$B:$B,18+1)) -> Billed tokens tie to billable usage | C22: =IF(INDEX(Data_Checks!$C:$C,18+1)="","",INDEX(Data_Checks!$C:$C,18+1)) -> 2027-01 | D22: =IF(INDEX(Data_Checks!$D:$D,18+1)="","",INDEX(Data_Checks!$D:$D,18+1)) -> 4910016675784 | E22: =IF(INDEX(Data_Checks!$E:$E,18+1)="","",INDEX(Data_Checks!$E:$E,18+1)) -> 4910016675784 | F22: =IF(INDEX(Data_Checks!$F:$F,18+1)="","",INDEX(Data_Checks!$F:$F,18+1)) -> 0 | G22: =IF(INDEX(Data_Checks!$G:$G,18+1)="","",INDEX(Data_Checks!$G:$G,18+1)) -> PASS | H22: =IF(INDEX(Data_Checks!$H:$H,18+1)="","",INDEX(Data_Checks!$H:$H,18+1)) -> 0 accounts billed for a different number of tokens than billable usage
A23: =IF(INDEX(Data_Checks!$A:$A,19+1)="","",INDEX(Data_Checks!$A:$A,19+1)) -> 4 | B23: =IF(INDEX(Data_Checks!$B:$B,19+1)="","",INDEX(Data_Checks!$B:$B,19+1)) -> Billed tokens tie to billable usage | C23: =IF(INDEX(Data_Checks!$C:$C,19+1)="","",INDEX(Data_Checks!$C:$C,19+1)) -> 2027-02 | D23: =IF(INDEX(Data_Checks!$D:$D,19+1)="","",INDEX(Data_Checks!$D:$D,19+1)) -> 5198170656463 | E23: =IF(INDEX(Data_Checks!$E:$E,19+1)="","",INDEX(Data_Checks!$E:$E,19+1)) -> 5198170656463 | F23: =IF(INDEX(Data_Checks!$F:$F,19+1)="","",INDEX(Data_Checks!$F:$F,19+1)) -> 0 | G23: =IF(INDEX(Data_Checks!$G:$G,19+1)="","",INDEX(Data_Checks!$G:$G,19+1)) -> PASS | H23: =IF(INDEX(Data_Checks!$H:$H,19+1)="","",INDEX(Data_Checks!$H:$H,19+1)) -> 0 accounts billed for a different number of tokens than billable usage
A24: =IF(INDEX(Data_Checks!$A:$A,20+1)="","",INDEX(Data_Checks!$A:$A,20+1)) -> 5 | B24: =IF(INDEX(Data_Checks!$B:$B,20+1)="","",INDEX(Data_Checks!$B:$B,20+1)) -> Every account with revenue has an invoice | C24: =IF(INDEX(Data_Checks!$C:$C,20+1)="","",INDEX(Data_Checks!$C:$C,20+1)) -> reporting window | D24: =IF(INDEX(Data_Checks!$D:$D,20+1)="","",INDEX(Data_Checks!$D:$D,20+1)) -> 0 | E24: =IF(INDEX(Data_Checks!$E:$E,20+1)="","",INDEX(Data_Checks!$E:$E,20+1)) -> 0 | F24: =IF(INDEX(Data_Checks!$F:$F,20+1)="","",INDEX(Data_Checks!$F:$F,20+1)) -> 0 | G24: =IF(INDEX(Data_Checks!$G:$G,20+1)="","",INDEX(Data_Checks!$G:$G,20+1)) -> PASS | H24: =IF(INDEX(Data_Checks!$H:$H,20+1)="","",INDEX(Data_Checks!$H:$H,20+1)) -> Every account with chargeable usage has an invoice
A25: =IF(INDEX(Data_Checks!$A:$A,21+1)="","",INDEX(Data_Checks!$A:$A,21+1)) -> 6 | B25: =IF(INDEX(Data_Checks!$B:$B,21+1)="","",INDEX(Data_Checks!$B:$B,21+1)) -> Invoices use the right unit price | C25: =IF(INDEX(Data_Checks!$C:$C,21+1)="","",INDEX(Data_Checks!$C:$C,21+1)) -> 2026-09 | D25: =IF(INDEX(Data_Checks!$D:$D,21+1)="","",INDEX(Data_Checks!$D:$D,21+1)) -> 8.0009597 | E25: =IF(INDEX(Data_Checks!$E:$E,21+1)="","",INDEX(Data_Checks!$E:$E,21+1)) -> 8 | F25: =IF(INDEX(Data_Checks!$F:$F,21+1)="","",INDEX(Data_Checks!$F:$F,21+1)) -> -0.000959722 | G25: =IF(INDEX(Data_Checks!$G:$G,21+1)="","",INDEX(Data_Checks!$G:$G,21+1)) -> PASS | H25: =IF(INDEX(Data_Checks!$H:$H,21+1)="","",INDEX(Data_Checks!$H:$H,21+1)) -> All invoices at the expected price
A26: =IF(INDEX(Data_Checks!$A:$A,22+1)="","",INDEX(Data_Checks!$A:$A,22+1)) -> 6 | B26: =IF(INDEX(Data_Checks!$B:$B,22+1)="","",INDEX(Data_Checks!$B:$B,22+1)) -> Invoices use the right unit price | C26: =IF(INDEX(Data_Checks!$C:$C,22+1)="","",INDEX(Data_Checks!$C:$C,22+1)) -> 2026-10 | D26: =IF(INDEX(Data_Checks!$D:$D,22+1)="","",INDEX(Data_Checks!$D:$D,22+1)) -> 21735.129 | E26: =IF(INDEX(Data_Checks!$E:$E,22+1)="","",INDEX(Data_Checks!$E:$E,22+1)) -> 21735.14 | F26: =IF(INDEX(Data_Checks!$F:$F,22+1)="","",INDEX(Data_Checks!$F:$F,22+1)) -> 0.010682876 | G26: =IF(INDEX(Data_Checks!$G:$G,22+1)="","",INDEX(Data_Checks!$G:$G,22+1)) -> PASS | H26: =IF(INDEX(Data_Checks!$H:$H,22+1)="","",INDEX(Data_Checks!$H:$H,22+1)) -> All invoices at the expected price
A27: =IF(INDEX(Data_Checks!$A:$A,23+1)="","",INDEX(Data_Checks!$A:$A,23+1)) -> 6 | B27: =IF(INDEX(Data_Checks!$B:$B,23+1)="","",INDEX(Data_Checks!$B:$B,23+1)) -> Invoices use the right unit price | C27: =IF(INDEX(Data_Checks!$C:$C,23+1)="","",INDEX(Data_Checks!$C:$C,23+1)) -> 2026-11 | D27: =IF(INDEX(Data_Checks!$D:$D,23+1)="","",INDEX(Data_Checks!$D:$D,23+1)) -> 71340.136 | E27: =IF(INDEX(Data_Checks!$E:$E,23+1)="","",INDEX(Data_Checks!$E:$E,23+1)) -> 71340.12 | F27: =IF(INDEX(Data_Checks!$F:$F,23+1)="","",INDEX(Data_Checks!$F:$F,23+1)) -> -0.015676633 | G27: =IF(INDEX(Data_Checks!$G:$G,23+1)="","",INDEX(Data_Checks!$G:$G,23+1)) -> PASS | H27: =IF(INDEX(Data_Checks!$H:$H,23+1)="","",INDEX(Data_Checks!$H:$H,23+1)) -> All invoices at the expected price
A28: =IF(INDEX(Data_Checks!$A:$A,24+1)="","",INDEX(Data_Checks!$A:$A,24+1)) -> 6 | B28: =IF(INDEX(Data_Checks!$B:$B,24+1)="","",INDEX(Data_Checks!$B:$B,24+1)) -> Invoices use the right unit price | C28: =IF(INDEX(Data_Checks!$C:$C,24+1)="","",INDEX(Data_Checks!$C:$C,24+1)) -> 2026-12 | D28: =IF(INDEX(Data_Checks!$D:$D,24+1)="","",INDEX(Data_Checks!$D:$D,24+1)) -> 137442.99 | E28: =IF(INDEX(Data_Checks!$E:$E,24+1)="","",INDEX(Data_Checks!$E:$E,24+1)) -> 137443.02 | F28: =IF(INDEX(Data_Checks!$F:$F,24+1)="","",INDEX(Data_Checks!$F:$F,24+1)) -> 0.02820446 | G28: =IF(INDEX(Data_Checks!$G:$G,24+1)="","",INDEX(Data_Checks!$G:$G,24+1)) -> PASS | H28: =IF(INDEX(Data_Checks!$H:$H,24+1)="","",INDEX(Data_Checks!$H:$H,24+1)) -> All invoices at the expected price
A29: =IF(INDEX(Data_Checks!$A:$A,25+1)="","",INDEX(Data_Checks!$A:$A,25+1)) -> 6 | B29: =IF(INDEX(Data_Checks!$B:$B,25+1)="","",INDEX(Data_Checks!$B:$B,25+1)) -> Invoices use the right unit price | C29: =IF(INDEX(Data_Checks!$C:$C,25+1)="","",INDEX(Data_Checks!$C:$C,25+1)) -> 2027-02 | D29: =IF(INDEX(Data_Checks!$D:$D,25+1)="","",INDEX(Data_Checks!$D:$D,25+1)) -> 186569.48 | E29: =IF(INDEX(Data_Checks!$E:$E,25+1)="","",INDEX(Data_Checks!$E:$E,25+1)) -> 186569.45 | F29: =IF(INDEX(Data_Checks!$F:$F,25+1)="","",INDEX(Data_Checks!$F:$F,25+1)) -> -0.026268446 | G29: =IF(INDEX(Data_Checks!$G:$G,25+1)="","",INDEX(Data_Checks!$G:$G,25+1)) -> PASS | H29: =IF(INDEX(Data_Checks!$H:$H,25+1)="","",INDEX(Data_Checks!$H:$H,25+1)) -> All invoices at the expected price
A30: =IF(INDEX(Data_Checks!$A:$A,26+1)="","",INDEX(Data_Checks!$A:$A,26+1)) -> 7 | B30: =IF(INDEX(Data_Checks!$B:$B,26+1)="","",INDEX(Data_Checks!$B:$B,26+1)) -> Free credit used stays within each account's grant | C30: =IF(INDEX(Data_Checks!$C:$C,26+1)="","",INDEX(Data_Checks!$C:$C,26+1)) -> all accounts | D30: =IF(INDEX(Data_Checks!$D:$D,26+1)="","",INDEX(Data_Checks!$D:$D,26+1)) -> 5 | E30: =IF(INDEX(Data_Checks!$E:$E,26+1)="","",INDEX(Data_Checks!$E:$E,26+1)) -> 5 | F30: =IF(INDEX(Data_Checks!$F:$F,26+1)="","",INDEX(Data_Checks!$F:$F,26+1)) -> 0 | G30: =IF(INDEX(Data_Checks!$G:$G,26+1)="","",INDEX(Data_Checks!$G:$G,26+1)) -> PASS | H30: =IF(INDEX(Data_Checks!$H:$H,26+1)="","",INDEX(Data_Checks!$H:$H,26+1)) -> 0 accounts used more free credit than granted
A31: =IF(INDEX(Data_Checks!$A:$A,27+1)="","",INDEX(Data_Checks!$A:$A,27+1)) -> 8 | B31: =IF(INDEX(Data_Checks!$B:$B,27+1)="","",INDEX(Data_Checks!$B:$B,27+1)) -> Gateway statement matches our logs | C31: =IF(INDEX(Data_Checks!$C:$C,27+1)="","",INDEX(Data_Checks!$C:$C,27+1)) -> digitalocean 2026-09 | D31: =IF(INDEX(Data_Checks!$D:$D,27+1)="","",INDEX(Data_Checks!$D:$D,27+1)) -> 426469684 | E31: =IF(INDEX(Data_Checks!$E:$E,27+1)="","",INDEX(Data_Checks!$E:$E,27+1)) -> 426000000 | F31: =IF(INDEX(Data_Checks!$F:$F,27+1)="","",INDEX(Data_Checks!$F:$F,27+1)) -> -0.01814859 | G31: =IF(INDEX(Data_Checks!$G:$G,27+1)="","",INDEX(Data_Checks!$G:$G,27+1)) -> PASS | H31: =IF(INDEX(Data_Checks!$H:$H,27+1)="","",INDEX(Data_Checks!$H:$H,27+1)) -> Statement is -0.11% vs our logs
A32: =IF(INDEX(Data_Checks!$A:$A,28+1)="","",INDEX(Data_Checks!$A:$A,28+1)) -> 8 | B32: =IF(INDEX(Data_Checks!$B:$B,28+1)="","",INDEX(Data_Checks!$B:$B,28+1)) -> Gateway statement matches our logs | C32: =IF(INDEX(Data_Checks!$C:$C,28+1)="","",INDEX(Data_Checks!$C:$C,28+1)) -> digitalocean 2026-10 | D32: =IF(INDEX(Data_Checks!$D:$D,28+1)="","",INDEX(Data_Checks!$D:$D,28+1)) -> 1055669350 | E32: =IF(INDEX(Data_Checks!$E:$E,28+1)="","",INDEX(Data_Checks!$E:$E,28+1)) -> 1056000000 | F32: =IF(INDEX(Data_Checks!$F:$F,28+1)="","",INDEX(Data_Checks!$F:$F,28+1)) -> 0.012776316 | G32: =IF(INDEX(Data_Checks!$G:$G,28+1)="","",INDEX(Data_Checks!$G:$G,28+1)) -> PASS | H32: =IF(INDEX(Data_Checks!$H:$H,28+1)="","",INDEX(Data_Checks!$H:$H,28+1)) -> Statement is 0.03% vs our logs
A33: =IF(INDEX(Data_Checks!$A:$A,29+1)="","",INDEX(Data_Checks!$A:$A,29+1)) -> 8 | B33: =IF(INDEX(Data_Checks!$B:$B,29+1)="","",INDEX(Data_Checks!$B:$B,29+1)) -> Gateway statement matches our logs | C33: =IF(INDEX(Data_Checks!$C:$C,29+1)="","",INDEX(Data_Checks!$C:$C,29+1)) -> digitalocean 2026-11 | D33: =IF(INDEX(Data_Checks!$D:$D,29+1)="","",INDEX(Data_Checks!$D:$D,29+1)) -> 2114605799 | E33: =IF(INDEX(Data_Checks!$E:$E,29+1)="","",INDEX(Data_Checks!$E:$E,29+1)) -> 2115000000 | F33: =IF(INDEX(Data_Checks!$F:$F,29+1)="","",INDEX(Data_Checks!$F:$F,29+1)) -> 0.015231927 | G33: =IF(INDEX(Data_Checks!$G:$G,29+1)="","",INDEX(Data_Checks!$G:$G,29+1)) -> PASS | H33: =IF(INDEX(Data_Checks!$H:$H,29+1)="","",INDEX(Data_Checks!$H:$H,29+1)) -> Statement is 0.02% vs our logs
A34: =IF(INDEX(Data_Checks!$A:$A,30+1)="","",INDEX(Data_Checks!$A:$A,30+1)) -> 8 | B34: =IF(INDEX(Data_Checks!$B:$B,30+1)="","",INDEX(Data_Checks!$B:$B,30+1)) -> Gateway statement matches our logs | C34: =IF(INDEX(Data_Checks!$C:$C,30+1)="","",INDEX(Data_Checks!$C:$C,30+1)) -> digitalocean 2026-12 | D34: =IF(INDEX(Data_Checks!$D:$D,30+1)="","",INDEX(Data_Checks!$D:$D,30+1)) -> 7466089971 | E34: =IF(INDEX(Data_Checks!$E:$E,30+1)="","",INDEX(Data_Checks!$E:$E,30+1)) -> 7466000000 | F34: =IF(INDEX(Data_Checks!$F:$F,30+1)="","",INDEX(Data_Checks!$F:$F,30+1)) -> -0.0034764794 | G34: =IF(INDEX(Data_Checks!$G:$G,30+1)="","",INDEX(Data_Checks!$G:$G,30+1)) -> PASS | H34: =IF(INDEX(Data_Checks!$H:$H,30+1)="","",INDEX(Data_Checks!$H:$H,30+1)) -> Statement is -0.0% vs our logs
A35: =IF(INDEX(Data_Checks!$A:$A,31+1)="","",INDEX(Data_Checks!$A:$A,31+1)) -> 8 | B35: =IF(INDEX(Data_Checks!$B:$B,31+1)="","",INDEX(Data_Checks!$B:$B,31+1)) -> Gateway statement matches our logs | C35: =IF(INDEX(Data_Checks!$C:$C,31+1)="","",INDEX(Data_Checks!$C:$C,31+1)) -> digitalocean 2027-01 | D35: =IF(INDEX(Data_Checks!$D:$D,31+1)="","",INDEX(Data_Checks!$D:$D,31+1)) -> 12737283801 | E35: =IF(INDEX(Data_Checks!$E:$E,31+1)="","",INDEX(Data_Checks!$E:$E,31+1)) -> 12737000000 | F35: =IF(INDEX(Data_Checks!$F:$F,31+1)="","",INDEX(Data_Checks!$F:$F,31+1)) -> -0.010966071 | G35: =IF(INDEX(Data_Checks!$G:$G,31+1)="","",INDEX(Data_Checks!$G:$G,31+1)) -> PASS | H35: =IF(INDEX(Data_Checks!$H:$H,31+1)="","",INDEX(Data_Checks!$H:$H,31+1)) -> Statement is -0.0% vs our logs
A36: =IF(INDEX(Data_Checks!$A:$A,32+1)="","",INDEX(Data_Checks!$A:$A,32+1)) -> 8 | B36: =IF(INDEX(Data_Checks!$B:$B,32+1)="","",INDEX(Data_Checks!$B:$B,32+1)) -> Gateway statement matches our logs | C36: =IF(INDEX(Data_Checks!$C:$C,32+1)="","",INDEX(Data_Checks!$C:$C,32+1)) -> digitalocean 2027-02 | D36: =IF(INDEX(Data_Checks!$D:$D,32+1)="","",INDEX(Data_Checks!$D:$D,32+1)) -> 14986734199 | E36: =IF(INDEX(Data_Checks!$E:$E,32+1)="","",INDEX(Data_Checks!$E:$E,32+1)) -> 14987000000 | F36: =IF(INDEX(Data_Checks!$F:$F,32+1)="","",INDEX(Data_Checks!$F:$F,32+1)) -> 0.010270551 | G36: =IF(INDEX(Data_Checks!$G:$G,32+1)="","",INDEX(Data_Checks!$G:$G,32+1)) -> PASS | H36: =IF(INDEX(Data_Checks!$H:$H,32+1)="","",INDEX(Data_Checks!$H:$H,32+1)) -> Statement is 0.0% vs our logs
A37: =IF(INDEX(Data_Checks!$A:$A,33+1)="","",INDEX(Data_Checks!$A:$A,33+1)) -> 8 | B37: =IF(INDEX(Data_Checks!$B:$B,33+1)="","",INDEX(Data_Checks!$B:$B,33+1)) -> Gateway statement matches our logs | C37: =IF(INDEX(Data_Checks!$C:$C,33+1)="","",INDEX(Data_Checks!$C:$C,33+1)) -> openrouter 2026-09 | D37: =IF(INDEX(Data_Checks!$D:$D,33+1)="","",INDEX(Data_Checks!$D:$D,33+1)) -> 1226175518 | E37: =IF(INDEX(Data_Checks!$E:$E,33+1)="","",INDEX(Data_Checks!$E:$E,33+1)) -> 1226000000 | F37: =IF(INDEX(Data_Checks!$F:$F,33+1)="","",INDEX(Data_Checks!$F:$F,33+1)) -> -0.0070031682 | G37: =IF(INDEX(Data_Checks!$G:$G,33+1)="","",INDEX(Data_Checks!$G:$G,33+1)) -> PASS | H37: =IF(INDEX(Data_Checks!$H:$H,33+1)="","",INDEX(Data_Checks!$H:$H,33+1)) -> Statement is -0.01% vs our logs
A38: =IF(INDEX(Data_Checks!$A:$A,34+1)="","",INDEX(Data_Checks!$A:$A,34+1)) -> 8 | B38: =IF(INDEX(Data_Checks!$B:$B,34+1)="","",INDEX(Data_Checks!$B:$B,34+1)) -> Gateway statement matches our logs | C38: =IF(INDEX(Data_Checks!$C:$C,34+1)="","",INDEX(Data_Checks!$C:$C,34+1)) -> openrouter 2026-10 | D38: =IF(INDEX(Data_Checks!$D:$D,34+1)="","",INDEX(Data_Checks!$D:$D,34+1)) -> 10059494302 | E38: =IF(INDEX(Data_Checks!$E:$E,34+1)="","",INDEX(Data_Checks!$E:$E,34+1)) -> 10059000000 | F38: =IF(INDEX(Data_Checks!$F:$F,34+1)="","",INDEX(Data_Checks!$F:$F,34+1)) -> -0.01972265 | G38: =IF(INDEX(Data_Checks!$G:$G,34+1)="","",INDEX(Data_Checks!$G:$G,34+1)) -> PASS | H38: =IF(INDEX(Data_Checks!$H:$H,34+1)="","",INDEX(Data_Checks!$H:$H,34+1)) -> Statement is -0.0% vs our logs
A39: =IF(INDEX(Data_Checks!$A:$A,35+1)="","",INDEX(Data_Checks!$A:$A,35+1)) -> 8 | B39: =IF(INDEX(Data_Checks!$B:$B,35+1)="","",INDEX(Data_Checks!$B:$B,35+1)) -> Gateway statement matches our logs | C39: =IF(INDEX(Data_Checks!$C:$C,35+1)="","",INDEX(Data_Checks!$C:$C,35+1)) -> openrouter 2026-11 | D39: =IF(INDEX(Data_Checks!$D:$D,35+1)="","",INDEX(Data_Checks!$D:$D,35+1)) -> 46369863095 | E39: =IF(INDEX(Data_Checks!$E:$E,35+1)="","",INDEX(Data_Checks!$E:$E,35+1)) -> 46370000000 | F39: =IF(INDEX(Data_Checks!$F:$F,35+1)="","",INDEX(Data_Checks!$F:$F,35+1)) -> 0.0054625095 | G39: =IF(INDEX(Data_Checks!$G:$G,35+1)="","",INDEX(Data_Checks!$G:$G,35+1)) -> PASS | H39: =IF(INDEX(Data_Checks!$H:$H,35+1)="","",INDEX(Data_Checks!$H:$H,35+1)) -> Statement is 0.0% vs our logs
A40: =IF(INDEX(Data_Checks!$A:$A,36+1)="","",INDEX(Data_Checks!$A:$A,36+1)) -> 8 | B40: =IF(INDEX(Data_Checks!$B:$B,36+1)="","",INDEX(Data_Checks!$B:$B,36+1)) -> Gateway statement matches our logs | C40: =IF(INDEX(Data_Checks!$C:$C,36+1)="","",INDEX(Data_Checks!$C:$C,36+1)) -> openrouter 2026-12 | D40: =IF(INDEX(Data_Checks!$D:$D,36+1)="","",INDEX(Data_Checks!$D:$D,36+1)) -> 165493359479 | E40: =IF(INDEX(Data_Checks!$E:$E,36+1)="","",INDEX(Data_Checks!$E:$E,36+1)) -> 165493000000 | F40: =IF(INDEX(Data_Checks!$F:$F,36+1)="","",INDEX(Data_Checks!$F:$F,36+1)) -> -0.014343212 | G40: =IF(INDEX(Data_Checks!$G:$G,36+1)="","",INDEX(Data_Checks!$G:$G,36+1)) -> PASS | H40: =IF(INDEX(Data_Checks!$H:$H,36+1)="","",INDEX(Data_Checks!$H:$H,36+1)) -> Statement is -0.0% vs our logs
A41: =IF(INDEX(Data_Checks!$A:$A,37+1)="","",INDEX(Data_Checks!$A:$A,37+1)) -> 8 | B41: =IF(INDEX(Data_Checks!$B:$B,37+1)="","",INDEX(Data_Checks!$B:$B,37+1)) -> Gateway statement matches our logs | C41: =IF(INDEX(Data_Checks!$C:$C,37+1)="","",INDEX(Data_Checks!$C:$C,37+1)) -> openrouter 2027-02 | D41: =IF(INDEX(Data_Checks!$D:$D,37+1)="","",INDEX(Data_Checks!$D:$D,37+1)) -> 370518908817 | E41: =IF(INDEX(Data_Checks!$E:$E,37+1)="","",INDEX(Data_Checks!$E:$E,37+1)) -> 370519000000 | F41: =IF(INDEX(Data_Checks!$F:$F,37+1)="","",INDEX(Data_Checks!$F:$F,37+1)) -> 0.0036382017 | G41: =IF(INDEX(Data_Checks!$G:$G,37+1)="","",INDEX(Data_Checks!$G:$G,37+1)) -> PASS | H41: =IF(INDEX(Data_Checks!$H:$H,37+1)="","",INDEX(Data_Checks!$H:$H,37+1)) -> Statement is 0.0% vs our logs
...

Sheet Monthly
A1: =Data_Params!$B$14&" | Usage and revenue by month" -> Example Co (synthetic data) | Usage and revenue by month
A2: Formulas only: every number reads the Data_ sheets. Tokens in billions, $ in thousands.
A4: Line | B4: =EDATE(Data_Params!$B$3,0) -> 46082 | C4: =EDATE(Data_Params!$B$3,1) -> 46113 | D4: =EDATE(Data_Params!$B$3,2) -> 46143 | E4: =EDATE(Data_Params!$B$3,3) -> 46174 | F4: =EDATE(Data_Params!$B$3,4) -> 46204 | G4: =EDATE(Data_Params!$B$3,5) -> 46235 | H4: =EDATE(Data_Params!$B$3,6) -> 46266 | I4: =EDATE(Data_Params!$B$3,7) -> 46296 | J4: =EDATE(Data_Params!$B$3,8) -> 46327 | K4: =EDATE(Data_Params!$B$3,9) -> 46357 | L4: =EDATE(Data_Params!$B$3,10) -> 46388 | M4: =EDATE(Data_Params!$B$3,11) -> 46419
A5: Billable tokens (B)
A6: Enterprise | B6: =SUMIFS(Data_Monthly!$F:$F,Data_Monthly!$A:$A,B$4,Data_Monthly!$B:$B,"enterprise")/1000000000 -> 0 | C6: =SUMIFS(Data_Monthly!$F:$F,Data_Monthly!$A:$A,C$4,Data_Monthly!$B:$B,"enterprise")/1000000000 -> 0 | D6: =SUMIFS(Data_Monthly!$F:$F,Data_Monthly!$A:$A,D$4,Data_Monthly!$B:$B,"enterprise")/1000000000 -> 0 | E6: =SUMIFS(Data_Monthly!$F:$F,Data_Monthly!$A:$A,E$4,Data_Monthly!$B:$B,"enterprise")/1000000000 -> 0 | F6: =SUMIFS(Data_Monthly!$F:$F,Data_Monthly!$A:$A,F$4,Data_Monthly!$B:$B,"enterprise")/1000000000 -> 0 | G6: =SUMIFS(Data_Monthly!$F:$F,Data_Monthly!$A:$A,G$4,Data_Monthly!$B:$B,"enterprise")/1000000000 -> 0 | H6: =SUMIFS(Data_Monthly!$F:$F,Data_Monthly!$A:$A,H$4,Data_Monthly!$B:$B,"enterprise")/1000000000 -> 0 | I6: =SUMIFS(Data_Monthly!$F:$F,Data_Monthly!$A:$A,I$4,Data_Monthly!$B:$B,"enterprise")/1000000000 -> 584.37278 | ... M6: =SUMIFS(Data_Monthly!$F:$F,Data_Monthly!$A:$A,M$4,Data_Monthly!$B:$B,"enterprise")/1000000000 -> 4615.8421
A7: Self-serve | B7: =SUMIFS(Data_Monthly!$F:$F,Data_Monthly!$A:$A,B$4,Data_Monthly!$B:$B,"self_serve")/1000000000 -> 0 | C7: =SUMIFS(Data_Monthly!$F:$F,Data_Monthly!$A:$A,C$4,Data_Monthly!$B:$B,"self_serve")/1000000000 -> 0 | D7: =SUMIFS(Data_Monthly!$F:$F,Data_Monthly!$A:$A,D$4,Data_Monthly!$B:$B,"self_serve")/1000000000 -> 0 | E7: =SUMIFS(Data_Monthly!$F:$F,Data_Monthly!$A:$A,E$4,Data_Monthly!$B:$B,"self_serve")/1000000000 -> 0 | F7: =SUMIFS(Data_Monthly!$F:$F,Data_Monthly!$A:$A,F$4,Data_Monthly!$B:$B,"self_serve")/1000000000 -> 0 | G7: =SUMIFS(Data_Monthly!$F:$F,Data_Monthly!$A:$A,G$4,Data_Monthly!$B:$B,"self_serve")/1000000000 -> 0 | H7: =SUMIFS(Data_Monthly!$F:$F,Data_Monthly!$A:$A,H$4,Data_Monthly!$B:$B,"self_serve")/1000000000 -> 6.0433854 | I7: =SUMIFS(Data_Monthly!$F:$F,Data_Monthly!$A:$A,I$4,Data_Monthly!$B:$B,"self_serve")/1000000000 -> 53.119027 | ... M7: =SUMIFS(Data_Monthly!$F:$F,Data_Monthly!$A:$A,M$4,Data_Monthly!$B:$B,"self_serve")/1000000000 -> 1053.8774
A8: Gateways that don't pass customer IDs | B8: =SUMIFS(Data_Monthly!$F:$F,Data_Monthly!$A:$A,B$4,Data_Monthly!$B:$B,"gateway_aggregate")/1000000000 -> 0 | C8: =SUMIFS(Data_Monthly!$F:$F,Data_Monthly!$A:$A,C$4,Data_Monthly!$B:$B,"gateway_aggregate")/1000000000 -> 0 | D8: =SUMIFS(Data_Monthly!$F:$F,Data_Monthly!$A:$A,D$4,Data_Monthly!$B:$B,"gateway_aggregate")/1000000000 -> 0 | E8: =SUMIFS(Data_Monthly!$F:$F,Data_Monthly!$A:$A,E$4,Data_Monthly!$B:$B,"gateway_aggregate")/1000000000 -> 0 | F8: =SUMIFS(Data_Monthly!$F:$F,Data_Monthly!$A:$A,F$4,Data_Monthly!$B:$B,"gateway_aggregate")/1000000000 -> 0 | G8: =SUMIFS(Data_Monthly!$F:$F,Data_Monthly!$A:$A,G$4,Data_Monthly!$B:$B,"gateway_aggregate")/1000000000 -> 0 | H8: =SUMIFS(Data_Monthly!$F:$F,Data_Monthly!$A:$A,H$4,Data_Monthly!$B:$B,"gateway_aggregate")/1000000000 -> 1.2261755 | I8: =SUMIFS(Data_Monthly!$F:$F,Data_Monthly!$A:$A,I$4,Data_Monthly!$B:$B,"gateway_aggregate")/1000000000 -> 10.059494 | ... M8: =SUMIFS(Data_Monthly!$F:$F,Data_Monthly!$A:$A,M$4,Data_Monthly!$B:$B,"gateway_aggregate")/1000000000 -> 370.51891
A9: Unmatched accounts (fix the accounts source) | B9: =SUMIFS(Data_Monthly!$F:$F,Data_Monthly!$A:$A,B$4,Data_Monthly!$B:$B,"unmatched")/1000000000 -> 0 | C9: =SUMIFS(Data_Monthly!$F:$F,Data_Monthly!$A:$A,C$4,Data_Monthly!$B:$B,"unmatched")/1000000000 -> 0 | D9: =SUMIFS(Data_Monthly!$F:$F,Data_Monthly!$A:$A,D$4,Data_Monthly!$B:$B,"unmatched")/1000000000 -> 0 | E9: =SUMIFS(Data_Monthly!$F:$F,Data_Monthly!$A:$A,E$4,Data_Monthly!$B:$B,"unmatched")/1000000000 -> 0 | F9: =SUMIFS(Data_Monthly!$F:$F,Data_Monthly!$A:$A,F$4,Data_Monthly!$B:$B,"unmatched")/1000000000 -> 0 | G9: =SUMIFS(Data_Monthly!$F:$F,Data_Monthly!$A:$A,G$4,Data_Monthly!$B:$B,"unmatched")/1000000000 -> 0 | H9: =SUMIFS(Data_Monthly!$F:$F,Data_Monthly!$A:$A,H$4,Data_Monthly!$B:$B,"unmatched")/1000000000 -> 0 | I9: =SUMIFS(Data_Monthly!$F:$F,Data_Monthly!$A:$A,I$4,Data_Monthly!$B:$B,"unmatched")/1000000000 -> 0 | ... M9: =SUMIFS(Data_Monthly!$F:$F,Data_Monthly!$A:$A,M$4,Data_Monthly!$B:$B,"unmatched")/1000000000 -> 0
A10: Total billable tokens | B10: =SUM(B6:B9) -> 0 | C10: =SUM(C6:C9) -> 0 | D10: =SUM(D6:D9) -> 0 | E10: =SUM(E6:E9) -> 0 | F10: =SUM(F6:F9) -> 0 | G10: =SUM(G6:G9) -> 0 | H10: =SUM(H6:H9) -> 7.2695609 | I10: =SUM(I6:I9) -> 647.5513 | ... M10: =SUM(M6:M9) -> 6040.2384
A11: Days of data in month | B11: =SUMIFS(Data_Months!$B:$B,Data_Months!$A:$A,B$4) -> 31 | C11: =SUMIFS(Data_Months!$B:$B,Data_Months!$A:$A,C$4) -> 30 | D11: =SUMIFS(Data_Months!$B:$B,Data_Months!$A:$A,D$4) -> 31 | E11: =SUMIFS(Data_Months!$B:$B,Data_Months!$A:$A,E$4) -> 30 | F11: =SUMIFS(Data_Months!$B:$B,Data_Months!$A:$A,F$4) -> 31 | G11: =SUMIFS(Data_Months!$B:$B,Data_Months!$A:$A,G$4) -> 31 | H11: =SUMIFS(Data_Months!$B:$B,Data_Months!$A:$A,H$4) -> 16 | I11: =SUMIFS(Data_Months!$B:$B,Data_Months!$A:$A,I$4) -> 31 | ... M11: =SUMIFS(Data_Months!$B:$B,Data_Months!$A:$A,M$4) -> 28
A12: Tokens per day (B) | B12: =IF(B11=0,0,B10/B11) -> 0 | C12: =IF(C11=0,0,C10/C11) -> 0 | D12: =IF(D11=0,0,D10/D11) -> 0 | E12: =IF(E11=0,0,E10/E11) -> 0 | F12: =IF(F11=0,0,F10/F11) -> 0 | G12: =IF(G11=0,0,G10/G11) -> 0 | H12: =IF(H11=0,0,H10/H11) -> 0.45434755 | I12: =IF(I11=0,0,I10/I11) -> 20.888752 | ... M12: =IF(M11=0,0,M10/M11) -> 215.7228
A13: Enterprise, per day | B13: =IF(B11=0,0,B6/B11) -> 0 | C13: =IF(C11=0,0,C6/C11) -> 0 | D13: =IF(D11=0,0,D6/D11) -> 0 | E13: =IF(E11=0,0,E6/E11) -> 0 | F13: =IF(F11=0,0,F6/F11) -> 0 | G13: =IF(G11=0,0,G6/G11) -> 0 | H13: =IF(H11=0,0,H6/H11) -> 0 | I13: =IF(I11=0,0,I6/I11) -> 18.850735 | ... M13: =IF(M11=0,0,M6/M11) -> 164.85151
A14: Self-serve, per day | B14: =IF(B11=0,0,B7/B11) -> 0 | C14: =IF(C11=0,0,C7/C11) -> 0 | D14: =IF(D11=0,0,D7/D11) -> 0 | E14: =IF(E11=0,0,E7/E11) -> 0 | F14: =IF(F11=0,0,F7/F11) -> 0 | G14: =IF(G11=0,0,G7/G11) -> 0 | H14: =IF(H11=0,0,H7/H11) -> 0.37771159 | I14: =IF(I11=0,0,I7/I11) -> 1.713517 | ... M14: =IF(M11=0,0,M7/M11) -> 37.638477
A15: Gateways that don't pass customer IDs, per day | B15: =IF(B11=0,0,B8/B11) -> 0 | C15: =IF(C11=0,0,C8/C11) -> 0 | D15: =IF(D11=0,0,D8/D11) -> 0 | E15: =IF(E11=0,0,E8/E11) -> 0 | F15: =IF(F11=0,0,F8/F11) -> 0 | G15: =IF(G11=0,0,G8/G11) -> 0 | H15: =IF(H11=0,0,H8/H11) -> 0.07663597 | I15: =IF(I11=0,0,I8/I11) -> 0.32449982 | ... M15: =IF(M11=0,0,M8/M11) -> 13.232818
A16: Growth in tokens per day vs prior month | C16: =IF(B12=0,0,C12/B12-1) -> 0 | D16: =IF(C12=0,0,D12/C12-1) -> 0 | E16: =IF(D12=0,0,E12/D12-1) -> 0 | F16: =IF(E12=0,0,F12/E12-1) -> 0 | G16: =IF(F12=0,0,G12/F12-1) -> 0 | H16: =IF(G12=0,0,H12/G12-1) -> 0 | I16: =IF(H12=0,0,I12/H12-1) -> 44.97527 | J16: =IF(I12=0,0,J12/I12-1) -> 2.4920504 | ... M16: =IF(L12=0,0,M12/L12-1) -> 0.18411182
A18: Billable tokens by channel (B)
A19: =IF(INDEX(Data_Lists!$B:$B,1+1)="","",INDEX(Data_Lists!$B:$B,1+1)) -> direct | B19: =IF($A19="","",SUMIFS(Data_Monthly!$F:$F,Data_Monthly!$A:$A,B$4,Data_Monthly!$C:$C,$A19)/1000000000) -> 0 | C19: =IF($A19="","",SUMIFS(Data_Monthly!$F:$F,Data_Monthly!$A:$A,C$4,Data_Monthly!$C:$C,$A19)/1000000000) -> 0 | D19: =IF($A19="","",SUMIFS(Data_Monthly!$F:$F,Data_Monthly!$A:$A,D$4,Data_Monthly!$C:$C,$A19)/1000000000) -> 0 | E19: =IF($A19="","",SUMIFS(Data_Monthly!$F:$F,Data_Monthly!$A:$A,E$4,Data_Monthly!$C:$C,$A19)/1000000000) -> 0 | F19: =IF($A19="","",SUMIFS(Data_Monthly!$F:$F,Data_Monthly!$A:$A,F$4,Data_Monthly!$C:$C,$A19)/1000000000) -> 0 | G19: =IF($A19="","",SUMIFS(Data_Monthly!$F:$F,Data_Monthly!$A:$A,G$4,Data_Monthly!$C:$C,$A19)/1000000000) -> 0 | H19: =IF($A19="","",SUMIFS(Data_Monthly!$F:$F,Data_Monthly!$A:$A,H$4,Data_Monthly!$C:$C,$A19)/1000000000) -> 3.1006702 | I19: =IF($A19="","",SUMIFS(Data_Monthly!$F:$F,Data_Monthly!$A:$A,I$4,Data_Monthly!$C:$C,$A19)/1000000000) -> 620.09829 | ... M19: =IF($A19="","",SUMIFS(Data_Monthly!$F:$F,Data_Monthly!$A:$A,M$4,Data_Monthly!$C:$C,$A19)/1000000000) -> 5198.1707
A20: =IF(INDEX(Data_Lists!$B:$B,2+1)="","",INDEX(Data_Lists!$B:$B,2+1)) -> vercel | B20: =IF($A20="","",SUMIFS(Data_Monthly!$F:$F,Data_Monthly!$A:$A,B$4,Data_Monthly!$C:$C,$A20)/1000000000) -> 0 | C20: =IF($A20="","",SUMIFS(Data_Monthly!$F:$F,Data_Monthly!$A:$A,C$4,Data_Monthly!$C:$C,$A20)/1000000000) -> 0 | D20: =IF($A20="","",SUMIFS(Data_Monthly!$F:$F,Data_Monthly!$A:$A,D$4,Data_Monthly!$C:$C,$A20)/1000000000) -> 0 | E20: =IF($A20="","",SUMIFS(Data_Monthly!$F:$F,Data_Monthly!$A:$A,E$4,Data_Monthly!$C:$C,$A20)/1000000000) -> 0 | F20: =IF($A20="","",SUMIFS(Data_Monthly!$F:$F,Data_Monthly!$A:$A,F$4,Data_Monthly!$C:$C,$A20)/1000000000) -> 0 | G20: =IF($A20="","",SUMIFS(Data_Monthly!$F:$F,Data_Monthly!$A:$A,G$4,Data_Monthly!$C:$C,$A20)/1000000000) -> 0 | H20: =IF($A20="","",SUMIFS(Data_Monthly!$F:$F,Data_Monthly!$A:$A,H$4,Data_Monthly!$C:$C,$A20)/1000000000) -> 2.5162455 | I20: =IF($A20="","",SUMIFS(Data_Monthly!$F:$F,Data_Monthly!$A:$A,I$4,Data_Monthly!$C:$C,$A20)/1000000000) -> 16.337845 | ... M20: =IF($A20="","",SUMIFS(Data_Monthly!$F:$F,Data_Monthly!$A:$A,M$4,Data_Monthly!$C:$C,$A20)/1000000000) -> 456.56212
A21: =IF(INDEX(Data_Lists!$B:$B,3+1)="","",INDEX(Data_Lists!$B:$B,3+1)) -> openrouter | B21: =IF($A21="","",SUMIFS(Data_Monthly!$F:$F,Data_Monthly!$A:$A,B$4,Data_Monthly!$C:$C,$A21)/1000000000) -> 0 | C21: =IF($A21="","",SUMIFS(Data_Monthly!$F:$F,Data_Monthly!$A:$A,C$4,Data_Monthly!$C:$C,$A21)/1000000000) -> 0 | D21: =IF($A21="","",SUMIFS(Data_Monthly!$F:$F,Data_Monthly!$A:$A,D$4,Data_Monthly!$C:$C,$A21)/1000000000) -> 0 | E21: =IF($A21="","",SUMIFS(Data_Monthly!$F:$F,Data_Monthly!$A:$A,E$4,Data_Monthly!$C:$C,$A21)/1000000000) -> 0 | F21: =IF($A21="","",SUMIFS(Data_Monthly!$F:$F,Data_Monthly!$A:$A,F$4,Data_Monthly!$C:$C,$A21)/1000000000) -> 0 | G21: =IF($A21="","",SUMIFS(Data_Monthly!$F:$F,Data_Monthly!$A:$A,G$4,Data_Monthly!$C:$C,$A21)/1000000000) -> 0 | H21: =IF($A21="","",SUMIFS(Data_Monthly!$F:$F,Data_Monthly!$A:$A,H$4,Data_Monthly!$C:$C,$A21)/1000000000) -> 1.2261755 | I21: =IF($A21="","",SUMIFS(Data_Monthly!$F:$F,Data_Monthly!$A:$A,I$4,Data_Monthly!$C:$C,$A21)/1000000000) -> 10.059494 | ... M21: =IF($A21="","",SUMIFS(Data_Monthly!$F:$F,Data_Monthly!$A:$A,M$4,Data_Monthly!$C:$C,$A21)/1000000000) -> 370.51891
A22: =IF(INDEX(Data_Lists!$B:$B,4+1)="","",INDEX(Data_Lists!$B:$B,4+1)) -> digitalocean | B22: =IF($A22="","",SUMIFS(Data_Monthly!$F:$F,Data_Monthly!$A:$A,B$4,Data_Monthly!$C:$C,$A22)/1000000000) -> 0 | C22: =IF($A22="","",SUMIFS(Data_Monthly!$F:$F,Data_Monthly!$A:$A,C$4,Data_Monthly!$C:$C,$A22)/1000000000) -> 0 | D22: =IF($A22="","",SUMIFS(Data_Monthly!$F:$F,Data_Monthly!$A:$A,D$4,Data_Monthly!$C:$C,$A22)/1000000000) -> 0 | E22: =IF($A22="","",SUMIFS(Data_Monthly!$F:$F,Data_Monthly!$A:$A,E$4,Data_Monthly!$C:$C,$A22)/1000000000) -> 0 | F22: =IF($A22="","",SUMIFS(Data_Monthly!$F:$F,Data_Monthly!$A:$A,F$4,Data_Monthly!$C:$C,$A22)/1000000000) -> 0 | G22: =IF($A22="","",SUMIFS(Data_Monthly!$F:$F,Data_Monthly!$A:$A,G$4,Data_Monthly!$C:$C,$A22)/1000000000) -> 0 | H22: =IF($A22="","",SUMIFS(Data_Monthly!$F:$F,Data_Monthly!$A:$A,H$4,Data_Monthly!$C:$C,$A22)/1000000000) -> 0.42646968 | I22: =IF($A22="","",SUMIFS(Data_Monthly!$F:$F,Data_Monthly!$A:$A,I$4,Data_Monthly!$C:$C,$A22)/1000000000) -> 1.0556694 | ... M22: =IF($A22="","",SUMIFS(Data_Monthly!$F:$F,Data_Monthly!$A:$A,M$4,Data_Monthly!$C:$C,$A22)/1000000000) -> 14.986734
A23: =IF(INDEX(Data_Lists!$B:$B,5+1)="","",INDEX(Data_Lists!$B:$B,5+1)) | B23: =IF($A23="","",SUMIFS(Data_Monthly!$F:$F,Data_Monthly!$A:$A,B$4,Data_Monthly!$C:$C,$A23)/1000000000) | C23: =IF($A23="","",SUMIFS(Data_Monthly!$F:$F,Data_Monthly!$A:$A,C$4,Data_Monthly!$C:$C,$A23)/1000000000) | D23: =IF($A23="","",SUMIFS(Data_Monthly!$F:$F,Data_Monthly!$A:$A,D$4,Data_Monthly!$C:$C,$A23)/1000000000) | E23: =IF($A23="","",SUMIFS(Data_Monthly!$F:$F,Data_Monthly!$A:$A,E$4,Data_Monthly!$C:$C,$A23)/1000000000) | F23: =IF($A23="","",SUMIFS(Data_Monthly!$F:$F,Data_Monthly!$A:$A,F$4,Data_Monthly!$C:$C,$A23)/1000000000) | G23: =IF($A23="","",SUMIFS(Data_Monthly!$F:$F,Data_Monthly!$A:$A,G$4,Data_Monthly!$C:$C,$A23)/1000000000) | H23: =IF($A23="","",SUMIFS(Data_Monthly!$F:$F,Data_Monthly!$A:$A,H$4,Data_Monthly!$C:$C,$A23)/1000000000) | I23: =IF($A23="","",SUMIFS(Data_Monthly!$F:$F,Data_Monthly!$A:$A,I$4,Data_Monthly!$C:$C,$A23)/1000000000) | ... M23: =IF($A23="","",SUMIFS(Data_Monthly!$F:$F,Data_Monthly!$A:$A,M$4,Data_Monthly!$C:$C,$A23)/1000000000)
A24: =IF(INDEX(Data_Lists!$B:$B,6+1)="","",INDEX(Data_Lists!$B:$B,6+1)) | B24: =IF($A24="","",SUMIFS(Data_Monthly!$F:$F,Data_Monthly!$A:$A,B$4,Data_Monthly!$C:$C,$A24)/1000000000) | C24: =IF($A24="","",SUMIFS(Data_Monthly!$F:$F,Data_Monthly!$A:$A,C$4,Data_Monthly!$C:$C,$A24)/1000000000) | D24: =IF($A24="","",SUMIFS(Data_Monthly!$F:$F,Data_Monthly!$A:$A,D$4,Data_Monthly!$C:$C,$A24)/1000000000) | E24: =IF($A24="","",SUMIFS(Data_Monthly!$F:$F,Data_Monthly!$A:$A,E$4,Data_Monthly!$C:$C,$A24)/1000000000) | F24: =IF($A24="","",SUMIFS(Data_Monthly!$F:$F,Data_Monthly!$A:$A,F$4,Data_Monthly!$C:$C,$A24)/1000000000) | G24: =IF($A24="","",SUMIFS(Data_Monthly!$F:$F,Data_Monthly!$A:$A,G$4,Data_Monthly!$C:$C,$A24)/1000000000) | H24: =IF($A24="","",SUMIFS(Data_Monthly!$F:$F,Data_Monthly!$A:$A,H$4,Data_Monthly!$C:$C,$A24)/1000000000) | I24: =IF($A24="","",SUMIFS(Data_Monthly!$F:$F,Data_Monthly!$A:$A,I$4,Data_Monthly!$C:$C,$A24)/1000000000) | ... M24: =IF($A24="","",SUMIFS(Data_Monthly!$F:$F,Data_Monthly!$A:$A,M$4,Data_Monthly!$C:$C,$A24)/1000000000)
A25: =IF(INDEX(Data_Lists!$B:$B,7+1)="","",INDEX(Data_Lists!$B:$B,7+1)) | B25: =IF($A25="","",SUMIFS(Data_Monthly!$F:$F,Data_Monthly!$A:$A,B$4,Data_Monthly!$C:$C,$A25)/1000000000) | C25: =IF($A25="","",SUMIFS(Data_Monthly!$F:$F,Data_Monthly!$A:$A,C$4,Data_Monthly!$C:$C,$A25)/1000000000) | D25: =IF($A25="","",SUMIFS(Data_Monthly!$F:$F,Data_Monthly!$A:$A,D$4,Data_Monthly!$C:$C,$A25)/1000000000) | E25: =IF($A25="","",SUMIFS(Data_Monthly!$F:$F,Data_Monthly!$A:$A,E$4,Data_Monthly!$C:$C,$A25)/1000000000) | F25: =IF($A25="","",SUMIFS(Data_Monthly!$F:$F,Data_Monthly!$A:$A,F$4,Data_Monthly!$C:$C,$A25)/1000000000) | G25: =IF($A25="","",SUMIFS(Data_Monthly!$F:$F,Data_Monthly!$A:$A,G$4,Data_Monthly!$C:$C,$A25)/1000000000) | H25: =IF($A25="","",SUMIFS(Data_Monthly!$F:$F,Data_Monthly!$A:$A,H$4,Data_Monthly!$C:$C,$A25)/1000000000) | I25: =IF($A25="","",SUMIFS(Data_Monthly!$F:$F,Data_Monthly!$A:$A,I$4,Data_Monthly!$C:$C,$A25)/1000000000) | ... M25: =IF($A25="","",SUMIFS(Data_Monthly!$F:$F,Data_Monthly!$A:$A,M$4,Data_Monthly!$C:$C,$A25)/1000000000)
A26: =IF(INDEX(Data_Lists!$B:$B,8+1)="","",INDEX(Data_Lists!$B:$B,8+1)) | B26: =IF($A26="","",SUMIFS(Data_Monthly!$F:$F,Data_Monthly!$A:$A,B$4,Data_Monthly!$C:$C,$A26)/1000000000) | C26: =IF($A26="","",SUMIFS(Data_Monthly!$F:$F,Data_Monthly!$A:$A,C$4,Data_Monthly!$C:$C,$A26)/1000000000) | D26: =IF($A26="","",SUMIFS(Data_Monthly!$F:$F,Data_Monthly!$A:$A,D$4,Data_Monthly!$C:$C,$A26)/1000000000) | E26: =IF($A26="","",SUMIFS(Data_Monthly!$F:$F,Data_Monthly!$A:$A,E$4,Data_Monthly!$C:$C,$A26)/1000000000) | F26: =IF($A26="","",SUMIFS(Data_Monthly!$F:$F,Data_Monthly!$A:$A,F$4,Data_Monthly!$C:$C,$A26)/1000000000) | G26: =IF($A26="","",SUMIFS(Data_Monthly!$F:$F,Data_Monthly!$A:$A,G$4,Data_Monthly!$C:$C,$A26)/1000000000) | H26: =IF($A26="","",SUMIFS(Data_Monthly!$F:$F,Data_Monthly!$A:$A,H$4,Data_Monthly!$C:$C,$A26)/1000000000) | I26: =IF($A26="","",SUMIFS(Data_Monthly!$F:$F,Data_Monthly!$A:$A,I$4,Data_Monthly!$C:$C,$A26)/1000000000) | ... M26: =IF($A26="","",SUMIFS(Data_Monthly!$F:$F,Data_Monthly!$A:$A,M$4,Data_Monthly!$C:$C,$A26)/1000000000)
A28: Net revenue ($k)
A29: Enterprise | B29: =SUMIFS(Data_Monthly!$L:$L,Data_Monthly!$A:$A,B$4,Data_Monthly!$B:$B,"enterprise")/1000 -> 0 | C29: =SUMIFS(Data_Monthly!$L:$L,Data_Monthly!$A:$A,C$4,Data_Monthly!$B:$B,"enterprise")/1000 -> 0 | D29: =SUMIFS(Data_Monthly!$L:$L,Data_Monthly!$A:$A,D$4,Data_Monthly!$B:$B,"enterprise")/1000 -> 0 | E29: =SUMIFS(Data_Monthly!$L:$L,Data_Monthly!$A:$A,E$4,Data_Monthly!$B:$B,"enterprise")/1000 -> 0 | F29: =SUMIFS(Data_Monthly!$L:$L,Data_Monthly!$A:$A,F$4,Data_Monthly!$B:$B,"enterprise")/1000 -> 0 | G29: =SUMIFS(Data_Monthly!$L:$L,Data_Monthly!$A:$A,G$4,Data_Monthly!$B:$B,"enterprise")/1000 -> 0 | H29: =SUMIFS(Data_Monthly!$L:$L,Data_Monthly!$A:$A,H$4,Data_Monthly!$B:$B,"enterprise")/1000 -> 0 | I29: =SUMIFS(Data_Monthly!$L:$L,Data_Monthly!$A:$A,I$4,Data_Monthly!$B:$B,"enterprise")/1000 -> 51.935484 | ... M29: =SUMIFS(Data_Monthly!$L:$L,Data_Monthly!$A:$A,M$4,Data_Monthly!$B:$B,"enterprise")/1000 -> 190.11559
A30: Self-serve | B30: =SUMIFS(Data_Monthly!$L:$L,Data_Monthly!$A:$A,B$4,Data_Monthly!$B:$B,"self_serve")/1000 -> 0 | C30: =SUMIFS(Data_Monthly!$L:$L,Data_Monthly!$A:$A,C$4,Data_Monthly!$B:$B,"self_serve")/1000 -> 0 | D30: =SUMIFS(Data_Monthly!$L:$L,Data_Monthly!$A:$A,D$4,Data_Monthly!$B:$B,"self_serve")/1000 -> 0 | E30: =SUMIFS(Data_Monthly!$L:$L,Data_Monthly!$A:$A,E$4,Data_Monthly!$B:$B,"self_serve")/1000 -> 0 | F30: =SUMIFS(Data_Monthly!$L:$L,Data_Monthly!$A:$A,F$4,Data_Monthly!$B:$B,"self_serve")/1000 -> 0 | G30: =SUMIFS(Data_Monthly!$L:$L,Data_Monthly!$A:$A,G$4,Data_Monthly!$B:$B,"self_serve")/1000 -> 0 | H30: =SUMIFS(Data_Monthly!$L:$L,Data_Monthly!$A:$A,H$4,Data_Monthly!$B:$B,"self_serve")/1000 -> 0.12487794 | I30: =SUMIFS(Data_Monthly!$L:$L,Data_Monthly!$A:$A,I$4,Data_Monthly!$B:$B,"self_serve")/1000 -> 1.9118088 | ... M30: =SUMIFS(Data_Monthly!$L:$L,Data_Monthly!$A:$A,M$4,Data_Monthly!$B:$B,"self_serve")/1000 -> 42.805857
A31: Gateways that don't pass customer IDs | B31: =SUMIFS(Data_Monthly!$L:$L,Data_Monthly!$A:$A,B$4,Data_Monthly!$B:$B,"gateway_aggregate")/1000 -> 0 | C31: =SUMIFS(Data_Monthly!$L:$L,Data_Monthly!$A:$A,C$4,Data_Monthly!$B:$B,"gateway_aggregate")/1000 -> 0 | D31: =SUMIFS(Data_Monthly!$L:$L,Data_Monthly!$A:$A,D$4,Data_Monthly!$B:$B,"gateway_aggregate")/1000 -> 0 | E31: =SUMIFS(Data_Monthly!$L:$L,Data_Monthly!$A:$A,E$4,Data_Monthly!$B:$B,"gateway_aggregate")/1000 -> 0 | F31: =SUMIFS(Data_Monthly!$L:$L,Data_Monthly!$A:$A,F$4,Data_Monthly!$B:$B,"gateway_aggregate")/1000 -> 0 | G31: =SUMIFS(Data_Monthly!$L:$L,Data_Monthly!$A:$A,G$4,Data_Monthly!$B:$B,"gateway_aggregate")/1000 -> 0 | H31: =SUMIFS(Data_Monthly!$L:$L,Data_Monthly!$A:$A,H$4,Data_Monthly!$B:$B,"gateway_aggregate")/1000 -> 0.048924403 | I31: =SUMIFS(Data_Monthly!$L:$L,Data_Monthly!$A:$A,I$4,Data_Monthly!$B:$B,"gateway_aggregate")/1000 -> 0.40137382 | ... M31: =SUMIFS(Data_Monthly!$L:$L,Data_Monthly!$A:$A,M$4,Data_Monthly!$B:$B,"gateway_aggregate")/1000 -> 14.783704
A32: Unmatched accounts (fix the accounts source) | B32: =SUMIFS(Data_Monthly!$L:$L,Data_Monthly!$A:$A,B$4,Data_Monthly!$B:$B,"unmatched")/1000 -> 0 | C32: =SUMIFS(Data_Monthly!$L:$L,Data_Monthly!$A:$A,C$4,Data_Monthly!$B:$B,"unmatched")/1000 -> 0 | D32: =SUMIFS(Data_Monthly!$L:$L,Data_Monthly!$A:$A,D$4,Data_Monthly!$B:$B,"unmatched")/1000 -> 0 | E32: =SUMIFS(Data_Monthly!$L:$L,Data_Monthly!$A:$A,E$4,Data_Monthly!$B:$B,"unmatched")/1000 -> 0 | F32: =SUMIFS(Data_Monthly!$L:$L,Data_Monthly!$A:$A,F$4,Data_Monthly!$B:$B,"unmatched")/1000 -> 0 | G32: =SUMIFS(Data_Monthly!$L:$L,Data_Monthly!$A:$A,G$4,Data_Monthly!$B:$B,"unmatched")/1000 -> 0 | H32: =SUMIFS(Data_Monthly!$L:$L,Data_Monthly!$A:$A,H$4,Data_Monthly!$B:$B,"unmatched")/1000 -> 0 | I32: =SUMIFS(Data_Monthly!$L:$L,Data_Monthly!$A:$A,I$4,Data_Monthly!$B:$B,"unmatched")/1000 -> 0 | ... M32: =SUMIFS(Data_Monthly!$L:$L,Data_Monthly!$A:$A,M$4,Data_Monthly!$B:$B,"unmatched")/1000 -> 0
A33: Manual adjustments (Overrides tab) | B33: =SUMIFS(Overrides!$G$46:$G$75,Overrides!$F$46:$F$75,B$4)/1000 -> 0 | C33: =SUMIFS(Overrides!$G$46:$G$75,Overrides!$F$46:$F$75,C$4)/1000 -> 0 | D33: =SUMIFS(Overrides!$G$46:$G$75,Overrides!$F$46:$F$75,D$4)/1000 -> 0 | E33: =SUMIFS(Overrides!$G$46:$G$75,Overrides!$F$46:$F$75,E$4)/1000 -> 0 | F33: =SUMIFS(Overrides!$G$46:$G$75,Overrides!$F$46:$F$75,F$4)/1000 -> 0 | G33: =SUMIFS(Overrides!$G$46:$G$75,Overrides!$F$46:$F$75,G$4)/1000 -> 0 | H33: =SUMIFS(Overrides!$G$46:$G$75,Overrides!$F$46:$F$75,H$4)/1000 -> 0 | I33: =SUMIFS(Overrides!$G$46:$G$75,Overrides!$F$46:$F$75,I$4)/1000 -> 0 | ... M33: =SUMIFS(Overrides!$G$46:$G$75,Overrides!$F$46:$F$75,M$4)/1000 -> 0
A34: Total net revenue | B34: =SUM(B29:B33) -> 0 | C34: =SUM(C29:C33) -> 0 | D34: =SUM(D29:D33) -> 0 | E34: =SUM(E29:E33) -> 0 | F34: =SUM(F29:F33) -> 0 | G34: =SUM(G29:G33) -> 0 | H34: =SUM(H29:H33) -> 0.17380235 | I34: =SUM(I29:I33) -> 54.248666 | ... M34: =SUM(M29:M33) -> 247.70515
A35: of which enterprise true-ups | B35: =SUMIFS(Data_Monthly!$K:$K,Data_Monthly!$A:$A,B$4)/1000 -> 0 | C35: =SUMIFS(Data_Monthly!$K:$K,Data_Monthly!$A:$A,C$4)/1000 -> 0 | D35: =SUMIFS(Data_Monthly!$K:$K,Data_Monthly!$A:$A,D$4)/1000 -> 0 | E35: =SUMIFS(Data_Monthly!$K:$K,Data_Monthly!$A:$A,E$4)/1000 -> 0 | F35: =SUMIFS(Data_Monthly!$K:$K,Data_Monthly!$A:$A,F$4)/1000 -> 0 | G35: =SUMIFS(Data_Monthly!$K:$K,Data_Monthly!$A:$A,G$4)/1000 -> 0 | H35: =SUMIFS(Data_Monthly!$K:$K,Data_Monthly!$A:$A,H$4)/1000 -> 0 | I35: =SUMIFS(Data_Monthly!$K:$K,Data_Monthly!$A:$A,I$4)/1000 -> 31.419492 | ... M35: =SUMIFS(Data_Monthly!$K:$K,Data_Monthly!$A:$A,M$4)/1000 -> 27.556058
A36: Annualized run-rate ($k) | B36: =IF(B11=0,0,B34/B11*365) -> 0 | C36: =IF(C11=0,0,C34/C11*365) -> 0 | D36: =IF(D11=0,0,D34/D11*365) -> 0 | E36: =IF(E11=0,0,E34/E11*365) -> 0 | F36: =IF(F11=0,0,F34/F11*365) -> 0 | G36: =IF(G11=0,0,G34/G11*365) -> 0 | H36: =IF(H11=0,0,H34/H11*365) -> 3.9648661 | I36: =IF(I11=0,0,I34/I11*365) -> 638.7343 | ... M36: =IF(M11=0,0,M34/M11*365) -> 3229.0135
A37: Enterprise share of net revenue | B37: =IF(B34=0,0,B29/B34) -> 0 | C37: =IF(C34=0,0,C29/C34) -> 0 | D37: =IF(D34=0,0,D29/D34) -> 0 | E37: =IF(E34=0,0,E29/E34) -> 0 | F37: =IF(F34=0,0,F29/F34) -> 0 | G37: =IF(G34=0,0,G29/G34) -> 0 | H37: =IF(H34=0,0,H29/H34) -> 0 | I37: =IF(I34=0,0,I29/I34) -> 0.95735964 | ... M37: =IF(M34=0,0,M29/M34) -> 0.76750761
A38: Realized net price per M tokens ($) | B38: =IF(B10=0,0,B34/B10) -> 0 | C38: =IF(C10=0,0,C34/C10) -> 0 | D38: =IF(D10=0,0,D34/D10) -> 0 | E38: =IF(E10=0,0,E34/E10) -> 0 | F38: =IF(F10=0,0,F34/F10) -> 0 | G38: =IF(G10=0,0,G34/G10) -> 0 | H38: =IF(H10=0,0,H34/H10) -> 0.023908232 | I38: =IF(I10=0,0,I34/I10) -> 0.083775087 | ... M38: =IF(M10=0,0,M34/M10) -> 0.041009167
A40: Other lines
A41: List value of tokens ($k) | B41: =SUMIFS(Data_Monthly!$I:$I,Data_Monthly!$A:$A,B$4)/1000 -> 0 | C41: =SUMIFS(Data_Monthly!$I:$I,Data_Monthly!$A:$A,C$4)/1000 -> 0 | D41: =SUMIFS(Data_Monthly!$I:$I,Data_Monthly!$A:$A,D$4)/1000 -> 0 | E41: =SUMIFS(Data_Monthly!$I:$I,Data_Monthly!$A:$A,E$4)/1000 -> 0 | F41: =SUMIFS(Data_Monthly!$I:$I,Data_Monthly!$A:$A,F$4)/1000 -> 0 | G41: =SUMIFS(Data_Monthly!$I:$I,Data_Monthly!$A:$A,G$4)/1000 -> 0 | H41: =SUMIFS(Data_Monthly!$I:$I,Data_Monthly!$A:$A,H$4)/1000 -> 0.30532156 | I41: =SUMIFS(Data_Monthly!$I:$I,Data_Monthly!$A:$A,I$4)/1000 -> 27.197155 | ... M41: =SUMIFS(Data_Monthly!$I:$I,Data_Monthly!$A:$A,M$4)/1000 -> 253.69001
A42: Free credit used ($k) | B42: =SUMIFS(Data_Monthly!$H:$H,Data_Monthly!$A:$A,B$4)/1000 -> 0 | C42: =SUMIFS(Data_Monthly!$H:$H,Data_Monthly!$A:$A,C$4)/1000 -> 0 | D42: =SUMIFS(Data_Monthly!$H:$H,Data_Monthly!$A:$A,D$4)/1000 -> 0 | E42: =SUMIFS(Data_Monthly!$H:$H,Data_Monthly!$A:$A,E$4)/1000 -> 0 | F42: =SUMIFS(Data_Monthly!$H:$H,Data_Monthly!$A:$A,F$4)/1000 -> 0 | G42: =SUMIFS(Data_Monthly!$H:$H,Data_Monthly!$A:$A,G$4)/1000 -> 0 | H42: =SUMIFS(Data_Monthly!$H:$H,Data_Monthly!$A:$A,H$4)/1000 -> 0.12222719 | I42: =SUMIFS(Data_Monthly!$H:$H,Data_Monthly!$A:$A,I$4)/1000 -> 0.28133383 | ... M42: =SUMIFS(Data_Monthly!$H:$H,Data_Monthly!$A:$A,M$4)/1000 -> 0.447856
A43: Gateway fees ($k) | B43: =SUMIFS(Data_Monthly!$M:$M,Data_Monthly!$A:$A,B$4)/1000 -> 0 | C43: =SUMIFS(Data_Monthly!$M:$M,Data_Monthly!$A:$A,C$4)/1000 -> 0 | D43: =SUMIFS(Data_Monthly!$M:$M,Data_Monthly!$A:$A,D$4)/1000 -> 0 | E43: =SUMIFS(Data_Monthly!$M:$M,Data_Monthly!$A:$A,E$4)/1000 -> 0 | F43: =SUMIFS(Data_Monthly!$M:$M,Data_Monthly!$A:$A,F$4)/1000 -> 0 | G43: =SUMIFS(Data_Monthly!$M:$M,Data_Monthly!$A:$A,G$4)/1000 -> 0 | H43: =SUMIFS(Data_Monthly!$M:$M,Data_Monthly!$A:$A,H$4)/1000 -> 0.0092920223 | I43: =SUMIFS(Data_Monthly!$M:$M,Data_Monthly!$A:$A,I$4)/1000 -> 0.058981462 | ... M43: =SUMIFS(Data_Monthly!$M:$M,Data_Monthly!$A:$A,M$4)/1000 -> 1.7872256
